Workbook

Sheet Formulas_Overview
B3: From: | C3: ='Formulas_Progressive Report'!D4 -> 46235 | D3: To: | E3: =meta_sheet!A4-1 -> 46251
B4: Locations | D4: Daily | E4: MTD
B5: 66KV CR panel | D5: =HLOOKUP(E3,'Formulas_Progressive Report'!D4:AH67,2,0) -> 67929.429 | E5: =SUM('Formulas_Progressive Report'!D5:AH5) -> 1154121
B6: Cell Line Consumption | D6: =HLOOKUP($E$3,'Formulas_Departments Summary'!$D$3:$AH$18,2,0) -> 41051.655 | E6: =SUM('Formulas_Departments Summary'!D4:AH4) -> 690604.16
B7: Module line consumption | D7: =HLOOKUP($E$3,'Formulas_Departments Summary'!$D$3:$AH$18,3,0) -> 3366.5459 | E7: =SUM('Formulas_Departments Summary'!D5:AH5) -> 58520.597
B8: Transformer - 1. O/G Breaker | D8: =HLOOKUP($E$3,'Formulas_Progressive Report'!$D$4:$AH$67,6,0) -> 7684.0613 | E8: =SUM('Formulas_Progressive Report'!D9:AH9) -> 142415.18
B9: Transformer - 2. O/G Breaker | D9: =HLOOKUP($E$3,'Formulas_Progressive Report'!$D$4:$AH$67,7,0) -> 7886.526 | E9: =SUM('Formulas_Progressive Report'!D10:AH10) -> 133857.55
B10: Transformer - 3. O/G Breaker | D10: =HLOOKUP($E$3,'Formulas_Progressive Report'!$D$4:$AH$67,8,0) -> 8815.7028 | E10: =SUM('Formulas_Progressive Report'!D11:AH11) -> 150576.46
B11: Transformer - 4. O/G Breaker | D11: =HLOOKUP($E$3,'Formulas_Progressive Report'!$D$4:$AH$67,9,0) -> 7838.3902 | E11: =SUM('Formulas_Progressive Report'!D12:AH12) -> 134311.25
B12: Transformer - 5. O/G Breaker | D12: =HLOOKUP($E$3,'Formulas_Progressive Report'!$D$4:$AH$67,10,0) -> 12021.934 | E12: =SUM('Formulas_Progressive Report'!D13:AH13) -> 185245.45
B13: Total Transformer | D13: =SUM(D8:D12) -> 44246.614 | E13: =SUM(E8:E12) -> 746405.89
B14: DG - 1 (825) KVA | D14: =HLOOKUP($E$3,Formulas_DG!$D$3:$AH$13,2,0) -> 1.92 | E14: =SUM(Formulas_DG!D4:AH4) -> 3.392
B15: DG - 3 (1025) KVA | D15: =HLOOKUP($E$3,Formulas_DG!$D$3:$AH$13,3,0) -> 0 | E15: =SUM(Formulas_DG!D5:AH5) -> 0.512
B16: DG - 4 (1025) KVA | D16: =HLOOKUP($E$3,Formulas_DG!$D$3:$AH$13,4,0) -> 1.984 | E16: =SUM(Formulas_DG!D6:AH6) -> 3.52
B17: 11KV DG Cummins-4 | D17: =HLOOKUP($E$3,Formulas_DG!$D$3:$AH$13,5,0) -> 0 | E17: =SUM(Formulas_DG!D7:AH7) -> 0
B18: 11KV DG, MTU-5 | D18: =HLOOKUP($E$3,Formulas_DG!$D$3:$AH$13,6,0) -> 0.064 | E18: =SUM(Formulas_DG!D8:AH8) -> 0.192
B19: 11KV DG, Cummins-6 | D19: =HLOOKUP($E$3,Formulas_DG!$D$3:$AH$13,7,0) -> 0.192 | E19: =SUM(Formulas_DG!D9:AH9) -> 0.896
B20: 11KV DG, Cummins-7 | D20: =HLOOKUP($E$3,Formulas_DG!$D$3:$AH$13,8,0) -> 0.032 | E20: =SUM(Formulas_DG!D10:AH10) -> 0.352
B21: E & P office DG 1 - 365KVA | D21: =HLOOKUP($E$3,Formulas_DG!$D$3:$AH$13,9,0) -> 0 | E21: =SUM(Formulas_DG!D11:AH11) -> 847.39844
B22: E & P office DG 2 - 380KVA | D22: =HLOOKUP($E$3,Formulas_DG!$D$3:$AH$13,10,0) -> 0 | E22: =SUM(Formulas_DG!D12:AH12) -> 0
A23: =meta_sheet!A4-1 -> 46251 | B23: Total DG | D23: =SUM(D14:D22) -> 4.192 | E23: =SUM(E14:E22) -> 856.26244
B24: 60KW Solar ( Above ATS) | D24: =HLOOKUP($A$23,$E$104:$AJ$113,ROW(A2),0) -> 319 | E24: =AJ105 -> 4489.0938
B25: 20KW Solar (Above Canteen ) | D25: =HLOOKUP($A$23,$E$104:$AJ$113,ROW(A3),0) -> 89.53125 | E25: =AJ106 -> 935.76562
B26: 110kw Solar (LT Room) | D26: =HLOOKUP($A$23,$E$104:$AJ$113,ROW(A4),0) -> 0 | E26: =AJ107 -> 0
B27: 230KW Solar ( Chiller area 3 to 6) | D27: =HLOOKUP($A$23,$E$104:$AJ$113,ROW(A5),0) -> 692.112 | E27: =AJ108 -> 10266.53
B28: 180KW Solar (Hexa AHU Area) | D28: =HLOOKUP($A$23,$E$104:$AJ$113,ROW(A6),0) -> 16.6745 | E28: =AJ109 -> 514.009
B29: 40KW solar (PECVD Pump Room) | D29: =HLOOKUP($A$23,$E$104:$AJ$113,ROW(A7),0) -> 469.23 | E29: =AJ110 -> 7335.87
B30: Solar Near STP | D30: =HLOOKUP($A$23,$E$104:$AJ$113,ROW(A8),0) -> 13.52 | E30: =AJ111 -> 244.608
B31: Solar Near Gate-1 Pathway Staircase | D31: =HLOOKUP($A$23,$E$104:$AJ$113,ROW(A9),0) -> 185.024 | E31: =AJ112 -> 2902.4
B32: Solar Near Parking Area | D32: =HLOOKUP($A$23,$E$104:$AJ$113,ROW(A10),0) -> 0 | E32: =AJ113 -> 0
B33: Total Solar | D33: =SUM(D24:D32) -> 1785.0918 | E33: =SUM(E24:E32) -> 26688.277
C101: 2001 | D101: 1440
C102: =meta_sheet!A3 -> 46235 | D102: =meta_sheet!A4 -> 46252 | E102: =meta_sheet!A1 -> 0.25
B104: Sr. No. | C104: Locations | E104: =C102 -> 46235 | F104: =E104+1 -> 46236 | G104: =F104+1 -> 46237 | H104: =G104+1 -> 46238 | I104: =H104+1 -> 46239 | J104: =I104+1 -> 46240 | K104: =J104+1 -> 46241 | L104: =K104+1 -> 46242 | M104: =L104+1 -> 46243 | ... AI104: =AH104+1 -> 46265 | AJ104: Total
B105: 1 | C105: 60KW Solar ( Above ATS) | D105: 11878 | E105: 241.59375 | F105: 259.5 | G105: 212.8125 | H105: 219.09375 | I105: 253.71875 | J105: 259.46875 | K105: 170.8125 | L105: 283.375 | M105: 242.90625 | N105: 264.96875 | O105: 284.34375 | P105: 306.1875 | Q105: 313.34375 | R105: 289.75 | S105: 271.21875 | T105: 297 | U105: 319 | AJ105: =SUM(E105:AI105) -> 4489.0938
B106: 2 | C106: 20KW Solar (Above Canteen ) | D106: 11912 | E106: 71.0625 | F106: 77.625 | G106: 51.15625 | H106: 62.765625 | I106: 20.609375 | J106: 44.609375 | K106: 23.265625 | L106: 18.84375 | M106: 18.421875 | N106: 29.734375 | O106: 44.0625 | P106: 48.609375 | Q106: 92.9375 | R106: 87.625 | S106: 53.5 | T106: 101.40625 | U106: 89.53125 | AJ106: =SUM(E106:AI106) -> 935.76562
B107: 3 | C107: 110KW Solar (Above LT Room) | D107: 14181 | E107: 0 | F107: 0 | G107: 0 | H107: 0 | I107: 0 | J107: 0 | K107: 0 | L107: 0 | M107: 0 | N107: 0 | O107: 0 | P107: 0 | Q107: 0 | R107: 0 | S107: 0 | T107: 0 | U107: 0 | AJ107: =SUM(E107:AI107) -> 0
B108: 4 | C108: 230Kw Solar kit( chiller area 3to6) | D108: 23137 | E108: 535.708 | F108: 590.5125 | G108: 450.715 | H108: 482.597 | I108: 587.595 | J108: 548.901 | K108: 371.741 | L108: 609.605 | M108: 559.779 | N108: 685.03 | O108: 670.603 | P108: 679.339 | Q108: 713.989 | R108: 665.409 | S108: 645.913 | T108: 776.982 | U108: 692.112 | AJ108: =SUM(E108:AI108) -> 10266.53
B109: 5 | C109: 180KW Solar (Hexa AHU Area) | D109: 22957 | E109: 28.948 | F109: 32.01175 | G109: 23.1525 | H109: 26.54625 | I109: 30.6075 | J109: 28.97 | K109: 18.8025 | L109: 33.00725 | M109: 30.8265 | N109: 32.9435 | O109: 36.5055 | P109: 34.509 | Q109: 37.633 | R109: 29.7585 | S109: 33.73375 | T109: 39.379 | U109: 16.6745 | AJ109: =SUM(E109:AI109) -> 514.009
B110: 6 | C110: 40KW solar (PECVD Pump Room) | D110: 22958 | E110: 393.316 | F110: 422.342 | G110: 331.164 | H110: 350.814 | I110: 430.78 | J110: 402.748 | K110: 278.458 | L110: 447.386 | M110: 394.512 | N110: 474.616 | O110: 472.674 | P110: 479.836 | Q110: 505.148 | R110: 473.792 | S110: 466.346 | T110: 542.708 | U110: 469.23 | AJ110: =SUM(E110:AI110) -> 7335.87
...

Sheet Formulas_Consumption Summary
B3: From: | C3: ='Formulas_Departments Summary'!D3 -> 46235 | D3: To: | E3: =meta_sheet!A4-1 -> 46251 | H3: Locations - E & P office | J3: Daily | K3: MTD
B4: Locations - Manufacturing | D4: Daily | E4: MTD | H4: Import energy from EB
B5: Import energy from EB | H5: E & P office EB Incomer | J5: =HLOOKUP(E3,'Formulas_Progressive Report'!D4:AH67,64,0) -> 0 | K5: =SUM('Formulas_Progressive Report'!D64:AH64) -> 27153.95
B6: 66KV CR panel | D6: =HLOOKUP(E3,'Formulas_Progressive Report'!D4:AH67,2,0) -> 67929.429 | E6: =SUM('Formulas_Progressive Report'!D5:AH5) -> 1154121 | H6: MD recorded | J6: =VLOOKUP(E3,'PF & Demand'!K5:N37,3,0) -> 125.4683 | K6: =SUM('PF & Demand'!M7:M37) -> 1894.5862
B7: MD Recorded | D7: =VLOOKUP($E$3,'PF & Demand'!$K$6:$R$37,2,0) -> 2.9729669 | E7: =MAX('PF & Demand'!L7:L37) -> 3.100556 | H7: PF | J7: =VLOOKUP(E3,'PF & Demand'!K6:R37,6,0) -> 1 | K7: =MAX('PF & Demand'!Q7:Q37) -> 0.89309465
B8: PF | D8: =VLOOKUP($E$3,'PF & Demand'!$K$6:$R$37,6,0) -> 1 | E8: =IFERROR(AVERAGEIF('PF & Demand'!P6:P37,">0",'PF & Demand'!P6:P37),"-") -> 0.99998277 | H8: Captive Generation DG | J8: =SUM(J9:J10) -> 0.032 | K8: =SUM(K9:K10) -> 847.39844
B9: Captive Generation DG | D9: =SUM(D10:D16) -> 4.192 | E9: =SUM(E10:E16) -> 8.864 | H9: E & P office DG 1 - 365KVA | J9: =HLOOKUP($E$3,Formulas_DG!$D$3:$AH$13,ROW(C8),FALSE) -> 0.032 | K9: =SUM(Formulas_DG!D11:AH11) -> 847.39844
B10: =Formulas_Overview!B14 -> DG - 1 (825) KVA | D10: =Formulas_Overview!D14 -> 1.92 | E10: =Formulas_Overview!E14 -> 3.392 | H10: E & P office DG 2 - 380KVA | J10: =HLOOKUP($E$3,Formulas_DG!$D$3:$AH$13,ROW(C9),FALSE) -> 0 | K10: =SUM(Formulas_DG!D12:AH12) -> 0
B11: =Formulas_Overview!B15 -> DG - 3 (1025) KVA | D11: =Formulas_Overview!D15 -> 0 | E11: =Formulas_Overview!E15 -> 0.512
B12: =Formulas_Overview!B16 -> DG - 4 (1025) KVA | D12: =Formulas_Overview!D16 -> 1.984 | E12: =Formulas_Overview!E16 -> 3.52 | H12: Locations - Ware house | J12: Daily | K12: MTD
B13: =Formulas_Overview!B17 -> 11KV DG Cummins-4 | D13: =Formulas_Overview!D17 -> 0 | E13: =Formulas_Overview!E17 -> 0 | H13: Import energy from EB
B14: =Formulas_Overview!B18 -> 11KV DG, MTU-5 | D14: =Formulas_Overview!D18 -> 0.064 | E14: =Formulas_Overview!E18 -> 0.192 | H14: Ware house EB Incomer | J14: =HLOOKUP(E3,'Formulas_Progressive Report'!D4:AH67,65,0) -> #REF! | K14: =SUM('Formulas_Progressive Report'!D65:AH65) -> 5866.2312
B15: =Formulas_Overview!B19 -> 11KV DG, Cummins-6 | D15: =Formulas_Overview!D19 -> 0.192 | E15: =Formulas_Overview!E19 -> 0.896
B16: =Formulas_Overview!B20 -> 11KV DG, Cummins-7 | D16: =Formulas_Overview!D20 -> 0.032 | E16: =Formulas_Overview!E20 -> 0.352
B17: Generation Solar | D17: =SUM(D18:D26) -> 1785.0918 | E17: =SUM(E18:E26) -> 26688.277 | H17: MD recorded | J17: =VLOOKUP(E3,'PF & Demand'!K6:R37,4,0) -> 47.37132 | K17: =MAX('PF & Demand'!N7:N37) -> 49.015617
B18: 60KW Solar ( Above ATS) | D18: =Formulas_Overview!D24 -> 319 | E18: =Formulas_Overview!E24 -> 4489.0938 | H18: PF | J18: =VLOOKUP(E3,'PF & Demand'!K6:R37,4,0) -> 47.37132 | K18: =IFERROR(AVERAGEIF('PF & Demand'!R6:R37,">0",'PF & Demand'!R6:R37),"0") -> 0.50845369
B19: 20KW Solar (Above Canteen ) | D19: =Formulas_Overview!D25 -> 89.53125 | E19: =Formulas_Overview!E25 -> 935.76562 | H19: Captive Generation DG
B20: 110kw Solar (LT Room) | D20: =Formulas_Overview!D26 -> 0 | E20: =Formulas_Overview!E26 -> 0 | H20: Ware house DG - 125KVA | J20: =HLOOKUP(E3,Formulas_DG!D3:AH13,9,0) -> 0 | K20: =SUM(Formulas_DG!D13:AH13) -> 161.58398
B21: 230KW Solar ( Chiller area 3 to 6) | D21: =Formulas_Overview!D27 -> 692.112 | E21: =Formulas_Overview!E27 -> 10266.53
B22: 180KW Solar (Hexa AHU Area) | D22: =Formulas_Overview!D28 -> 16.6745 | E22: =Formulas_Overview!E28 -> 514.009
B23: 40KW solar (PECVD Pump Room) | D23: =Formulas_Overview!D29 -> 469.23 | E23: =Formulas_Overview!E29 -> 7335.87
B24: Solar Near STP | D24: =Formulas_Overview!D30 -> 13.52 | E24: =Formulas_Overview!E30 -> 244.608
B25: Solar Near Gate-1 Pathway Staircase | D25: =Formulas_Overview!D31 -> 185.024 | E25: =Formulas_Overview!E31 -> 2902.4
B26: Solar Near Parking Area | D26: =Formulas_Overview!D32 -> 0 | E26: =Formulas_Overview!E32 -> 0
B27: Total | D27: =SUM(D18:D26) -> 1785.0918 | E27: =SUM(E18:E26) -> 26688.277
B28: ETP Consumption
B29: Transformer - 5. O/G Breaker | D29: =Formulas_Overview!D12 -> 12021.934 | E29: =Formulas_Overview!E12 -> 185245.45
B30: STP Consumption
B31: MV - 1 New STP | D31: =HLOOKUP(E3,'Formulas_Progressive Report'!D4:AH67,43,0) -> 0 | E31: =SUM('Formulas_Progressive Report'!D47:AH47) -> 0
B32: Total | D32: =D6+D9+D17 -> 69718.713 | E32: =E6+E9+E17 -> 1180818.2
B34: EB Consumption
B35: Cell Line Consumption | D35: =HLOOKUP($E$3,'Formulas_Departments Summary'!$D$3:$AH$18,ROW(C2),0) -> 41051.655 | E35: =SUM('Formulas_Departments Summary'!D4:AH4) -> 690604.16
B36: Module Line Consumption | D36: =HLOOKUP($E$3,'Formulas_Departments Summary'!$D$3:$AH$18,ROW(C3),0) -> 3366.5459 | E36: =SUM('Formulas_Departments Summary'!D5:AH5) -> 58520.597
B37: DG Consumption
B38: DG consumption for Cell line | D38: =HLOOKUP($E$3,'Formulas_Departments Summary'!$D$3:$AH$7,ROW(C4),0) -> 4.16 | E38: =SUM('Formulas_Departments Summary'!D6:AH6) -> 8.512
B39: DG consumption for Module line | D39: =HLOOKUP($E$3,'Formulas_Departments Summary'!$D$3:$AH$7,ROW(C5),0) -> 0 | E39: =SUM('Formulas_Departments Summary'!D7:AH7) -> 0
B40: EB+DG+Solar
B41: Total Cell line consumption | D41: =HLOOKUP($E$3,'Formulas_Departments Summary'!$C$3:$AH$18,ROW(C6),0) -> 41055.815 | E41: =SUM('Formulas_Departments Summary'!D8:AH8) -> 690612.68
B42: Total Module line consumption | D42: =HLOOKUP($E$3,'Formulas_Departments Summary'!$C$3:$AH$18,ROW(C7),0) -> 3366.5459 | E42: =SUM('Formulas_Departments Summary'!D9:AH9) -> 58520.597
B43: Cell line CDA Consumption | D43: =HLOOKUP($E$3,'Formulas_Departments Summary'!$C$3:$AH$18,ROW(C8),0) -> 7101.5341 | E43: =SUM('Formulas_Departments Summary'!D10:AH10) -> 132910.45
...

Sheet Formulas_Carbon Footprint
B4: Locations - Manufacturing | D4: Daily | E4: MTD | I4: Daily | J4: MTD | L4: Locations - Ware house | N4: Daily | O4: MTD
B5: Import energy from EB | G5: Import energy from EB | L5: Import energy from EB
B6: 66KV CR panel | D6: ='Formulas_Consumption Summary'!D6 -> 67929.429 | E6: ='Formulas_Consumption Summary'!E6 -> 1154121 | G6: E & P office EB Incomer | I6: ='Formulas_Consumption Summary'!J5 -> 0 | J6: ='Formulas_Consumption Summary'!K5 -> 27153.95 | L6: Ware house EB Incomer | N6: ='Formulas_Consumption Summary'!J14 -> #REF! | O6: ='Formulas_Consumption Summary'!K14 -> 5866.2312
B7: Carbon Emission 1 | D7: =D6*0.8 -> 54343.543 | E7: =E6*0.8 -> 923296.84 | G7: Carbon Emission 1 | I7: =I6*0.8 -> 0 | J7: =J6*0.8 -> 21723.16 | L7: Carbon Emission 1 | N7: =N6*0.8 -> #REF! | O7: =O6*0.8 -> 4692.985
B8: Captive Generation DG | D8: ='Formulas_Consumption Summary'!D9 -> 4.192 | E8: ='Formulas_Consumption Summary'!E9 -> 8.864 | G8: Captive Generation DG | I8: ='Formulas_Consumption Summary'!J8 -> 0.032 | J8: ='Formulas_Consumption Summary'!K8 -> 847.39844 | L8: Captive Generation DG | N8: ='Formulas_Consumption Summary'!J19 -> 0 | O8: ='Formulas_Consumption Summary'!K19 -> 0
B9: ='Formulas_Consumption Summary'!B10 -> DG - 1 (825) KVA | D9: ='Formulas_Consumption Summary'!D10 -> 1.92 | E9: ='Formulas_Consumption Summary'!E10 -> 3.392 | G9: E & P office DG 1 - 365KVA | I9: ='Formulas_Consumption Summary'!J9 -> 0.032 | J9: ='Formulas_Consumption Summary'!K9 -> 847.39844 | L9: Ware house DG - 125KVA | N9: ='Formulas_Consumption Summary'!J19 -> 0 | O9: ='Formulas_Consumption Summary'!K19 -> 0
B10: ='Formulas_Consumption Summary'!B11 -> DG - 3 (1025) KVA | D10: ='Formulas_Consumption Summary'!D11 -> 0 | E10: ='Formulas_Consumption Summary'!E11 -> 0.512 | G10: E & P office DG 2 - 380KVA | I10: ='Formulas_Consumption Summary'!J10 -> 0 | J10: ='Formulas_Consumption Summary'!K10 -> 0
B11: ='Formulas_Consumption Summary'!B12 -> DG - 4 (1025) KVA | D11: ='Formulas_Consumption Summary'!D12 -> 1.984 | E11: ='Formulas_Consumption Summary'!E12 -> 3.52
B12: ='Formulas_Consumption Summary'!B13 -> 11KV DG Cummins-4 | D12: ='Formulas_Consumption Summary'!D13 -> 0 | E12: ='Formulas_Consumption Summary'!E13 -> 0
B13: ='Formulas_Consumption Summary'!B14 -> 11KV DG, MTU-5 | D13: ='Formulas_Consumption Summary'!D14 -> 0.064 | E13: ='Formulas_Consumption Summary'!E14 -> 0.192
B14: ='Formulas_Consumption Summary'!B15 -> 11KV DG, Cummins-6 | D14: ='Formulas_Consumption Summary'!D15 -> 0.192 | E14: ='Formulas_Consumption Summary'!E15 -> 0.896
B15: ='Formulas_Consumption Summary'!B16 -> 11KV DG, Cummins-7 | D15: ='Formulas_Consumption Summary'!D16 -> 0.032 | E15: ='Formulas_Consumption Summary'!E16 -> 0.352
B16: Carbon Emission 2 | D16: =D8*2.72 -> 11.40224 | E16: =E8*2.72 -> 24.11008 | G16: Carbon Emission 2 | I16: =I8*2.72 -> 0.08704 | J16: =J8*2.72 -> 2304.9238 | L16: Carbon Emission 2 | N16: =N8*2.72 -> 0 | O16: =O8*2.72 -> 0
B17: Generation Solar Roof top | D17: ='Formulas_Consumption Summary'!D17 -> 1785.0918 | E17: ='Formulas_Consumption Summary'!E17 -> 26688.277 | G17: Generation Solar Roof top | L17: Generation Solar Roof top
B18: 60KW Solar ( Above ATS) | D18: ='Formulas_Consumption Summary'!D18 -> 319 | E18: ='Formulas_Consumption Summary'!E18 -> 4489.0938
B19: 20KW Solar (Above Canteen ) | D19: ='Formulas_Consumption Summary'!D19 -> 89.53125 | E19: ='Formulas_Consumption Summary'!E19 -> 935.76562
B20: 110kw Solar (LT Room) | D20: ='Formulas_Consumption Summary'!D20 -> 0 | E20: ='Formulas_Consumption Summary'!E20 -> 0
B21: 230KW Solar ( Chiller area 3 to 6) | D21: ='Formulas_Consumption Summary'!D21 -> 692.112 | E21: ='Formulas_Consumption Summary'!E21 -> 10266.53
B22: 180KW Solar (Hexa AHU Area) | D22: ='Formulas_Consumption Summary'!D22 -> 16.6745 | E22: ='Formulas_Consumption Summary'!E22 -> 514.009 | G22: Carbon Emission 3 | I22: =I17*2.72 -> 0 | J22: =J17*2.72 -> 0 | L22: Carbon Emission 3 | N22: =N17*2.72 -> 0 | O22: =O17*2.72 -> 0
B23: 40KW solar (PECVD Pump Room) | D23: ='Formulas_Consumption Summary'!D23 -> 469.23 | E23: ='Formulas_Consumption Summary'!E23 -> 7335.87 | G23: Net Carbon Emission | I23: =I7+I16+I22 -> 0.08704 | J23: =J7+J16+J22 -> 24028.084 | L23: Net Carbon Emission | N23: =N7+N16+N22 -> #REF! | O23: =O7+O16+O22 -> 4692.985
B24: Solar Near STP | D24: ='Formulas_Consumption Summary'!D24 -> 13.52 | E24: ='Formulas_Consumption Summary'!E24 -> 244.608
B25: Solar Near Gate-1 Pathway Staircase | D25: ='Formulas_Consumption Summary'!D25 -> 185.024 | E25: ='Formulas_Consumption Summary'!E25 -> 2902.4
B26: Solar Near Parking Area | D26: ='Formulas_Consumption Summary'!D26 -> 0 | E26: ='Formulas_Consumption Summary'!E26 -> 0
B27: ='Formulas_Consumption Summary'!B27 -> Total | D27: ='Formulas_Consumption Summary'!D27 -> 1785.0918 | E27: ='Formulas_Consumption Summary'!E27 -> 26688.277
B28: Carbon Emission 3 | D28: =D17*2.72 -> 4855.4496 | E28: =E17*2.72 -> 72592.113
B29: Net Carbon Emission | D29: =D7+D16+D28 -> 59210.395 | E29: =E7+E16+E28 -> 995913.06

Sheet Formulas_Progressive Report
B4: Sr. No. | C4: Locations | D4: =meta_sheet!A3 -> 46235 | E4: =D4+1 -> 46236 | F4: =E4+1 -> 46237 | G4: =F4+1 -> 46238 | H4: =G4+1 -> 46239 | I4: =H4+1 -> 46240 | J4: =I4+1 -> 46241 | K4: =J4+1 -> 46242 | L4: =K4+1 -> 46243 | ... AH4: =AG4+1 -> 46265 | AK4: =Formulas_Past!AN4 -> Red | AL4: =Formulas_Past!AO4 -> Yell
B5: 1 | C5: 66 KV CR Panel | D5: ='DAta 123'!E5 -> 67760.811 | E5: ='DAta 123'!F5 -> 69006.198 | F5: ='DAta 123'!G5 -> 69183.967 | G5: ='DAta 123'!H5 -> 69125.461 | H5: ='DAta 123'!I5 -> 67790.106 | I5: ='DAta 123'!J5 -> 62611.515 | J5: ='DAta 123'!K5 -> 67102.037 | K5: ='DAta 123'!L5 -> 67291.225 | ... AH5: ='DAta 123'!AI5 -> 0 | AK5: =Formulas_Past!AN5 -> 74727.798 | AL5: =Formulas_Past!AO5 -> 61140.926
B6: =B5+1 -> 2 | C6: 11KV Incomer Breaker | D6: ='DAta 123'!E6 -> 67629.59 | E6: ='DAta 123'!F6 -> 68891.633 | F6: ='DAta 123'!G6 -> 69101.568 | G6: ='DAta 123'!H6 -> 69043.571 | H6: ='DAta 123'!I6 -> 67724.6 | I6: ='DAta 123'!J6 -> 62496.768 | J6: ='DAta 123'!K6 -> 66938.88 | K6: ='DAta 123'!L6 -> 67012.519 | ... AH6: ='DAta 123'!AI6 -> 0 | AK6: =Formulas_Past!AN6 -> 74535.965 | AL6: =Formulas_Past!AO6 -> 60983.971
B7: =B6+1 -> 3 | C7: 11KV ATS O-G Breaker | D7: ='DAta 123'!E7 -> 43807.403 | E7: ='DAta 123'!F7 -> 44806.827 | F7: ='DAta 123'!G7 -> 45115.897 | G7: ='DAta 123'!H7 -> 44830.898 | H7: ='DAta 123'!I7 -> 43341.824 | I7: ='DAta 123'!J7 -> 40592.384 | J7: ='DAta 123'!K7 -> 44196.864 | K7: ='DAta 123'!L7 -> 44222.464 | ... AH7: ='DAta 123'!AI7 -> 0 | AK7: =Formulas_Past!AN7 -> 48884.85 | AL7: =Formulas_Past!AO7 -> 39996.695
B8: =B7+1 -> 4 | C8: 11KV Module & Cell O-G Breaker | D8: ='DAta 123'!E8 -> 24271.146 | E8: ='DAta 123'!F8 -> 24525.141 | F8: ='DAta 123'!G8 -> 24434.005 | G8: ='DAta 123'!H8 -> 24642.219 | H8: ='DAta 123'!I8 -> 24818.05 | I8: ='DAta 123'!J8 -> 22311.09 | J8: ='DAta 123'!K8 -> 23171.873 | K8: ='DAta 123'!L8 -> 23233.536 | ... AH8: ='DAta 123'!AI8 -> 0 | AK8: =Formulas_Past!AN8 -> 26133.62 | AL8: =Formulas_Past!AO8 -> 21382.053
B9: =B8+1 -> 5 | C9: Transformer - 1. OG Breaker | D9: ='DAta 123'!E9 -> 5374.7851 | E9: ='DAta 123'!F9 -> 8070.5085 | F9: ='DAta 123'!G9 -> 8279.6127 | G9: ='DAta 123'!H9 -> 7685.4845 | H9: ='DAta 123'!I9 -> 8337.9287 | I9: ='DAta 123'!J9 -> 8758.7753 | J9: ='DAta 123'!K9 -> 9327.4598 | K9: ='DAta 123'!L9 -> 8875.9973 | ... AH9: ='DAta 123'!AI9 -> 0 | AK9: =Formulas_Past!AN9 -> 6457.8416 | AL9: =Formulas_Past!AO9 -> 5283.6886
B10: =B9+1 -> 6 | C10: Transformer - 2. OG Breaker | D10: ='DAta 123'!E10 -> 10382.215 | E10: ='DAta 123'!F10 -> 7540.1112 | F10: ='DAta 123'!G10 -> 7628.2099 | G10: ='DAta 123'!H10 -> 7683.8236 | H10: ='DAta 123'!I10 -> 7842.0644 | I10: ='DAta 123'!J10 -> 7114.8561 | J10: ='DAta 123'!K10 -> 7340.579 | K10: ='DAta 123'!L10 -> 7899.075 | ... AH10: ='DAta 123'!AI10 -> 0 | AK10: =Formulas_Past!AN10 -> 10866.439 | AL10: =Formulas_Past!AO10 -> 8890.7231
B11: =B10+1 -> 7 | C11: Transformer - 3. OG Breaker | D11: ='DAta 123'!E11 -> 8874.3089 | E11: ='DAta 123'!F11 -> 9107.8254 | F11: ='DAta 123'!G11 -> 9026.5635 | G11: ='DAta 123'!H11 -> 9012.6371 | H11: ='DAta 123'!I11 -> 8469.1395 | I11: ='DAta 123'!J11 -> 8449.7009 | J11: ='DAta 123'!K11 -> 9058.8941 | K11: ='DAta 123'!L11 -> 8975.3774 | ... AH11: ='DAta 123'!AI11 -> 0 | AK11: =Formulas_Past!AN11 -> 9626.9399 | AL11: =Formulas_Past!AO11 -> 7876.5872
B12: =B11+1 -> 8 | C12: Transformer - 4. OG Breaker | D12: ='DAta 123'!E12 -> 8031.9552 | E12: ='DAta 123'!F12 -> 8014.9001 | F12: ='DAta 123'!G12 -> 7963.5959 | G12: ='DAta 123'!H12 -> 7824.7485 | H12: ='DAta 123'!I12 -> 7862.9315 | I12: ='DAta 123'!J12 -> 7967.5184 | J12: ='DAta 123'!K12 -> 8062.4206 | K12: ='DAta 123'!L12 -> 7993.3093 | ... AH12: ='DAta 123'!AI12 -> 0 | AK12: =Formulas_Past!AN12 -> 8666.1763 | AL12: =Formulas_Past!AO12 -> 7090.5079
B13: =B12+1 -> 9 | C13: Transformer - 5. OG Breaker | D13: ='DAta 123'!E13 -> 10985.541 | E13: ='DAta 123'!F13 -> 11920.991 | F13: ='DAta 123'!G13 -> 12090.214 | G13: ='DAta 123'!H13 -> 12437.779 | H13: ='DAta 123'!I13 -> 10653.522 | I13: ='DAta 123'!J13 -> 8140.4529 | J13: ='DAta 123'!K13 -> 10250.83 | K13: ='DAta 123'!L13 -> 10306.564 | ... AH13: ='DAta 123'!AI13 -> 0 | AK13: =Formulas_Past!AN13 -> 13448.27 | AL13: =Formulas_Past!AO13 -> 11003.13
B14: =B13+1 -> 10 | C14: 11KV DG Cummins-4 | D14: ='DAta 123'!E14 -> 0 | E14: ='DAta 123'!F14 -> 0 | F14: ='DAta 123'!G14 -> 0 | G14: ='DAta 123'!H14 -> 0 | H14: ='DAta 123'!I14 -> 0 | I14: ='DAta 123'!J14 -> 0 | J14: ='DAta 123'!K14 -> 0 | K14: ='DAta 123'!L14 -> 0 | ... AH14: ='DAta 123'!AI14 -> 0 | AK14: =Formulas_Past!AN14 -> 1710.016 | AL14: =Formulas_Past!AO14 -> 1399.104
B15: =B14+1 -> 11 | C15: 11KV DG, MTU-5 | D15: ='DAta 123'!E15 -> 0 | E15: ='DAta 123'!F15 -> 0 | F15: ='DAta 123'!G15 -> 0 | G15: ='DAta 123'!H15 -> 0 | H15: ='DAta 123'!I15 -> 0 | I15: ='DAta 123'!J15 -> 0.064 | J15: ='DAta 123'!K15 -> 0 | K15: ='DAta 123'!L15 -> 0 | ... AH15: ='DAta 123'!AI15 -> 0 | AK15: =Formulas_Past!AN15 -> 292.28672 | AL15: =Formulas_Past!AO15 -> 239.14368
B16: =B15+1 -> 12 | C16: 11KV DG, Cummins-6 | D16: ='DAta 123'!E16 -> 0 | E16: ='DAta 123'!F16 -> 0 | F16: ='DAta 123'!G16 -> 0.192 | G16: ='DAta 123'!H16 -> 0 | H16: ='DAta 123'!I16 -> 0 | I16: ='DAta 123'!J16 -> 0.192 | J16: ='DAta 123'!K16 -> 0 | K16: ='DAta 123'!L16 -> 0 | ... AH16: ='DAta 123'!AI16 -> 0 | AK16: =Formulas_Past!AN16 -> 485.4976 | AL16: =Formulas_Past!AO16 -> 397.22531
B17: =B16+1 -> 13 | C17: TOTAL HT DG | D17: =SUM(D14:D16) -> 0 | E17: =SUM(E14:E16) -> 0 | F17: =SUM(F14:F16) -> 0.192 | G17: =SUM(G14:G16) -> 0 | H17: =SUM(H14:H16) -> 0 | I17: =SUM(I14:I16) -> 0.256 | J17: =SUM(J14:J16) -> 0 | K17: =SUM(K14:K16) -> 0 | ... AH17: =SUM(AH14:AH16) -> 0 | AK17: =Formulas_Past!AN17 -> 2487.8003 | AL17: =Formulas_Past!AO17 -> 2035.473
B18: =B17+1 -> 14 | C18: Chiller - 4 | D18: ='DAta 123'!E17 -> 574.93148 | E18: ='DAta 123'!F17 -> 852.0239 | F18: ='DAta 123'!G17 -> 799.4351 | G18: ='DAta 123'!H17 -> 788.26553 | H18: ='DAta 123'!I17 -> 456.192 | I18: ='DAta 123'!J17 -> 45.056 | J18: ='DAta 123'!K17 -> 491.008 | K18: ='DAta 123'!L17 -> 423.936 | ... AH18: ='DAta 123'!AI17 -> 0 | AK18: =Formulas_Past!AN18 -> 831.19223 | AL18: =Formulas_Past!AO18 -> 680.06637
B19: =B18+1 -> 15 | C19: CDA - 2 | D19: ='DAta 123'!E18 -> 0 | E19: ='DAta 123'!F18 -> 0 | F19: ='DAta 123'!G18 -> 0.512 | G19: ='DAta 123'!H18 -> 0 | H19: ='DAta 123'!I18 -> 1196.6776 | I19: ='DAta 123'!J18 -> 2039.2193 | J19: ='DAta 123'!K18 -> 2118.7375 | K19: ='DAta 123'!L18 -> 1755.4762 | ... AH19: ='DAta 123'!AI18 -> 0 | AK19: =Formulas_Past!AN19 -> 880.08448 | AL19: =Formulas_Past!AO19 -> 720.06912
B20: =B19+1 -> 16 | C20: CDA - 1 | D20: ='DAta 123'!E19 -> 2290.1872 | E20: ='DAta 123'!F19 -> 2293.1311 | F20: ='DAta 123'!G19 -> 2294.9824 | G20: ='DAta 123'!H19 -> 2297.7578 | H20: ='DAta 123'!I19 -> 2314.663 | I20: ='DAta 123'!J19 -> 2329.5165 | J20: ='DAta 123'!K19 -> 2324.4815 | K20: ='DAta 123'!L19 -> 2321.5512 | ... AH20: ='DAta 123'!AI19 -> 0 | AK20: =Formulas_Past!AN20 -> 2365.3486 | AL20: =Formulas_Past!AO20 -> 1935.2852
B21: =B20+1 -> 17 | C21: PMCC HVAC High Side | D21: ='DAta 123'!E20 -> 0.26574059 | E21: ='DAta 123'!F20 -> 0.2656129 | F21: ='DAta 123'!G20 -> 0.26573744 | G21: ='DAta 123'!H20 -> 0.27139832 | H21: ='DAta 123'!I20 -> 0.27157994 | I21: ='DAta 123'!J20 -> 0.27898592 | J21: ='DAta 123'!K20 -> 0.2723629 | K21: ='DAta 123'!L20 -> 0.27175269 | ... AH21: ='DAta 123'!AI20 -> 0 | AK21: =Formulas_Past!AN21 -> 0.29959568 | AL21: =Formulas_Past!AO21 -> 0.24512374
B22: =B21+1 -> 18 | C22: UPW Panel | D22: ='DAta 123'!E21 -> 0 | E22: ='DAta 123'!F21 -> 0 | F22: ='DAta 123'!G21 -> 0 | G22: ='DAta 123'!H21 -> 0 | H22: ='DAta 123'!I21 -> 0 | I22: ='DAta 123'!J21 -> 0 | J22: ='DAta 123'!K21 -> 0 | K22: ='DAta 123'!L21 -> 0 | ... AH22: ='DAta 123'!AI21 -> 0 | AK22: =Formulas_Past!AN22 -> 0 | AL22: =Formulas_Past!AO22 -> 0
B23: =B22+1 -> 19 | C23: Chiller - 3 | D23: ='DAta 123'!E22 -> 0 | E23: ='DAta 123'!F22 -> 0 | F23: ='DAta 123'!G22 -> 0 | G23: ='DAta 123'!H22 -> 0 | H23: ='DAta 123'!I22 -> 0 | I23: ='DAta 123'!J22 -> 0 | J23: ='DAta 123'!K22 -> 0 | K23: ='DAta 123'!L22 -> 0 | ... AH23: ='DAta 123'!AI22 -> 0 | AK23: =Formulas_Past!AN23 -> 0 | AL23: =Formulas_Past!AO23 -> 0
B24: =B23+1 -> 20 | C24: Chiller - 2 | D24: ='DAta 123'!E23 -> 780.97809 | E24: ='DAta 123'!F23 -> 3244.288 | F24: ='DAta 123'!G23 -> 3199.8012 | G24: ='DAta 123'!H23 -> 2845.6055 | H24: ='DAta 123'!I23 -> 2838.784 | I24: ='DAta 123'!J23 -> 2827.1022 | J24: ='DAta 123'!K23 -> 2684.4261 | K24: ='DAta 123'!L23 -> 2913.0754 | ... AH24: ='DAta 123'!AI23 -> 0 | AK24: =Formulas_Past!AN24 -> 2130.6187 | AL24: =Formulas_Past!AO24 -> 1743.2335
B25: =B24+1 -> 21 | C25: Chiller - 1 | D25: ='DAta 123'!E24 -> 2825.8245 | E25: ='DAta 123'!F24 -> 0 | F25: ='DAta 123'!G24 -> 0 | G25: ='DAta 123'!H24 -> 0 | H25: ='DAta 123'!I24 -> 0 | I25: ='DAta 123'!J24 -> 0 | J25: ='DAta 123'!K24 -> 0 | K25: ='DAta 123'!L24 -> 0 | ... AH25: ='DAta 123'!AI24 -> 0 | AK25: =Formulas_Past!AN25 -> 3850.0935 | AL25: =Formulas_Past!AO25 -> 3150.0765
B26: =B25+1 -> 22 | C26: CDA - 3 | D26: ='DAta 123'!E25 -> 2230.1411 | E26: ='DAta 123'!F25 -> 2233.5582 | F26: ='DAta 123'!G25 -> 2237.0321 | G26: ='DAta 123'!H25 -> 2237.003 | H26: ='DAta 123'!I25 -> 2253.334 | I26: ='DAta 123'!J25 -> 2247.9472 | J26: ='DAta 123'!K25 -> 2262.8949 | K26: ='DAta 123'!L25 -> 2252.8495 | ... AH26: ='DAta 123'!AI25 -> 0 | AK26: =Formulas_Past!AN26 -> 2230.9357 | AL26: =Formulas_Past!AO26 -> 1825.311
B27: =B26+1 -> 23 | C27: Fire Pump | D27: ='DAta 123'!E26 -> 1.28125 | E27: ='DAta 123'!F26 -> 2.0039062 | F27: ='DAta 123'!G26 -> 1.2929688 | G27: ='DAta 123'!H26 -> 1.7460938 | H27: ='DAta 123'!I26 -> 1.4038086 | I27: ='DAta 123'!J26 -> 1.9149064 | J27: ='DAta 123'!K26 -> 1.5055037 | K27: ='DAta 123'!L26 -> 1.5458984 | ... AH27: ='DAta 123'!AI26 -> 0 | AK27: =Formulas_Past!AN27 -> 4.7832189 | AL27: =Formulas_Past!AO27 -> 3.9135427
B28: =B27+1 -> 24 | C28: 60KW Solar ( Above ATS) | D28: ='DAta 123'!E27 -> 241.59375 | E28: ='DAta 123'!F27 -> 259.5 | F28: ='DAta 123'!G27 -> 212.8125 | G28: ='DAta 123'!H27 -> 219.09375 | H28: ='DAta 123'!I27 -> 253.71875 | I28: ='DAta 123'!J27 -> 259.46875 | J28: ='DAta 123'!K27 -> 170.8125 | K28: ='DAta 123'!L27 -> 283.375 | ... AH28: ='DAta 123'!AI27 -> 0 | AK28: =Formulas_Past!AN28 -> 394.8878 | AL28: =Formulas_Past!AO28 -> 323.09002
B29: =B28+1 -> 25 | C29: CDA - 4 | D29: ='DAta 123'!E28 -> 2226.2816 | E29: ='DAta 123'!F28 -> 2383.8764 | F29: ='DAta 123'!G28 -> 2334.4724 | G29: ='DAta 123'!H28 -> 2295.6125 | H29: ='DAta 123'!I28 -> 2300.7892 | I29: ='DAta 123'!J28 -> 1756.9383 | J29: ='DAta 123'!K28 -> 1704.25 | K29: ='DAta 123'!L28 -> 2409.4752 | ... AH29: ='DAta 123'!AI28 -> 0 | AK29: =Formulas_Past!AN29 -> 2408.8216 | AL29: =Formulas_Past!AO29 -> 1970.8541
... B58: =B57+1 -> 54 | C58: Module UPS3 | D58: ='DAta 123'!E57 -> 71.0625 | E58: ='DAta 123'!F57 -> 77.625 | F58: ='DAta 123'!G57 -> 51.15625 | G58: ='DAta 123'!H57 -> 62.765625 | H58: ='DAta 123'!I57 -> 20.609375 | I58: ='DAta 123'!J57 -> 44.609375 | J58: ='DAta 123'!K57 -> 23.265625 | K58: ='DAta 123'!L57 -> 18.84375 | ... AH58: ='DAta 123'!AI57 -> 0 | AK58: =Formulas_Past!AN58 -> 82.846522 | AL58: =Formulas_Past!AO58 -> 67.783518
B59: =B58+1 -> 55 | C59: 20KW Solar (Above Canteen ) | D59: ='DAta 123'!E57 -> 71.0625 | E59: ='DAta 123'!F57 -> 77.625 | F59: ='DAta 123'!G57 -> 51.15625 | G59: ='DAta 123'!H57 -> 62.765625 | H59: ='DAta 123'!I57 -> 20.609375 | I59: ='DAta 123'!J57 -> 44.609375 | J59: ='DAta 123'!K57 -> 23.265625 | K59: ='DAta 123'!L57 -> 18.84375 | ... AH59: ='DAta 123'!AI57 -> 0 | AK59: =Formulas_Past!AN59 -> 82.846522 | AL59: =Formulas_Past!AO59 -> 67.783518
B60: =B59+1 -> 56 | C60: MV-2 SMSB | D60: ='DAta 123'!E58 -> 0 | E60: ='DAta 123'!F58 -> 0 | F60: ='DAta 123'!G58 -> 0 | G60: ='DAta 123'!H58 -> 0 | H60: ='DAta 123'!I58 -> 0 | I60: ='DAta 123'!J58 -> 0 | J60: ='DAta 123'!K58 -> 0 | K60: ='DAta 123'!L58 -> 0 | ... AH60: ='DAta 123'!AI58 -> 0 | AK60: =Formulas_Past!AN60 -> 0 | AL60: =Formulas_Past!AO60 -> 0
B61: =B60+1 -> 57 | C61: Unit 1 DG 1 - 365KVA | D61: ='DAta 123'!E59 -> 0 | E61: ='DAta 123'!F59 -> 207.57812 | F61: ='DAta 123'!G59 -> 0 | G61: ='DAta 123'!H59 -> 0 | H61: ='DAta 123'!I59 -> 36 | I61: ='DAta 123'!J59 -> 0 | J61: ='DAta 123'!K59 -> 0 | K61: ='DAta 123'!L59 -> 81.828125 | ... AH61: ='DAta 123'!AI59 -> 0 | AK61: =Formulas_Past!AN61 -> 66.642383 | AL61: =Formulas_Past!AO61 -> 54.525586
B62: =B61+1 -> 58 | C62: Unit 1 DG 2 - 380KVA | D62: ='DAta 123'!E60 -> 0 | E62: ='DAta 123'!F60 -> 0 | F62: ='DAta 123'!G60 -> 0 | G62: ='DAta 123'!H60 -> 0 | H62: ='DAta 123'!I60 -> 0 | I62: ='DAta 123'!J60 -> 0 | J62: ='DAta 123'!K60 -> 0 | K62: ='DAta 123'!L60 -> 0 | ... AH62: ='DAta 123'!AI60 -> 0 | AK62: =Formulas_Past!AN62 -> 0 | AL62: =Formulas_Past!AO62 -> 0
B63: =B62+1 -> 59 | C63: JINCHEN LAMINATOR 2 | D63: ='DAta 123'!E61 -> 882.49425 | E63: ='DAta 123'!F61 -> 901.6552 | F63: ='DAta 123'!G61 -> 878.7804 | G63: ='DAta 123'!H61 -> 881.5108 | H63: ='DAta 123'!I61 -> 911.0168 | I63: ='DAta 123'!J61 -> 891.9408 | J63: ='DAta 123'!K61 -> 905.3736 | K63: ='DAta 123'!L61 -> 883.88051 | ... AH63: ='DAta 123'!AI61 -> 0 | AK63: =Formulas_Past!AN63 -> 957.49246 | AL63: =Formulas_Past!AO63 -> 783.40293
B64: =B63+1 -> 60 | C64: Unit 1 EB Incomer | D64: ='DAta 123'!E62 -> 1522.6203 | E64: ='DAta 123'!F62 -> 868.43755 | F64: ='DAta 123'!G62 -> 1891.6047 | G64: ='DAta 123'!H62 -> 1908.8125 | H64: ='DAta 123'!I62 -> 1813.5 | I64: ='DAta 123'!J62 -> 1902.2792 | J64: ='DAta 123'!K62 -> 1833.4083 | K64: ='DAta 123'!L62 -> 1103.475 | ... AH64: ='DAta 123'!AI62 -> 0 | AK64: =Formulas_Past!AN64 -> 2004.1726 | AL64: =Formulas_Past!AO64 -> 1639.7776
B65: =B64+1 -> 61 | C65: Unit 5 EB Incomer | D65: ='DAta 123'!E63 -> 423.51562 | E65: ='DAta 123'!F63 -> 99.00625 | F65: ='DAta 123'!G63 -> 399.05312 | G65: ='DAta 123'!H63 -> 414.3625 | H65: ='DAta 123'!I63 -> 386.76715 | I65: ='DAta 123'!J63 -> 386.93927 | J65: ='DAta 123'!K63 -> 396.7139 | K65: ='DAta 123'!L63 -> 382.97031 | ... AH65: ='DAta 123'!AI63 -> 0 | AK65: =Formulas_Past!AN65 -> 381.82735 | AL65: =Formulas_Past!AO65 -> 312.4042
B66: =B65+1 -> 62 | C66: Unit 5 DG Incomer | D66: ='DAta 123'!E64 -> 0 | E66: ='DAta 123'!F64 -> 0.3515625 | F66: ='DAta 123'!G64 -> 0 | G66: ='DAta 123'!H64 -> 0 | H66: ='DAta 123'!I64 -> 0 | I66: ='DAta 123'!J64 -> 0 | J66: ='DAta 123'!K64 -> 0 | K66: ='DAta 123'!L64 -> 1.7695312 | ... AH66: ='DAta 123'!AI64 -> 0 | AK66: =Formulas_Past!AN66 -> 8.9061328 | AL66: =Formulas_Past!AO66 -> 7.2868359
B67: =B66+1 -> 63 | C67: 90KW Solar (Above LT Room) | D67: ='DAta 123'!E65 -> 0 | E67: ='DAta 123'!F65 -> 0 | F67: ='DAta 123'!G65 -> 0 | G67: ='DAta 123'!H65 -> 0 | H67: ='DAta 123'!I65 -> 0 | I67: ='DAta 123'!J65 -> 0 | J67: ='DAta 123'!K65 -> 0 | K67: ='DAta 123'!L65 -> 0 | ... AH67: ='DAta 123'!AI65 -> 0 | AK67: =Formulas_Past!AN67 -> 0 | AL67: =Formulas_Past!AO67 -> 0
B68: =B67+1 -> 64 | C68: 120Kw Solar kit( chiller area 3to6) | D68: ='DAta 123'!E66 -> 535.708 | E68: ='DAta 123'!F66 -> 590.5125 | F68: ='DAta 123'!G66 -> 450.715 | G68: ='DAta 123'!H66 -> 482.597 | H68: ='DAta 123'!I66 -> 587.595 | I68: ='DAta 123'!J66 -> 548.901 | J68: ='DAta 123'!K66 -> 371.741 | K68: ='DAta 123'!L66 -> 609.605 | ... AH68: ='DAta 123'!AI66 -> 0 | AK68: =Formulas_Past!AN68 -> 650.56692 | AL68: =Formulas_Past!AO68 -> 532.28203
B69: =B68+1 -> 65 | C69: 40 kW Solar (PECVD Pump Room) | D69: ='DAta 123'!E67 -> 28.948 | E69: ='DAta 123'!F67 -> 32.01175 | F69: ='DAta 123'!G67 -> 23.1525 | G69: ='DAta 123'!H67 -> 26.54625 | H69: ='DAta 123'!I67 -> 30.6075 | I69: ='DAta 123'!J67 -> 28.97 | J69: ='DAta 123'!K67 -> 18.8025 | K69: ='DAta 123'!L67 -> 33.00725 | ... AH69: ='DAta 123'!AI67 -> 0 | AK69: =Formulas_Past!AN69 -> 34.182008 | AL69: =Formulas_Past!AO69 -> 27.967097
B70: =B69+1 -> 66 | C70: 220Kw Solar(terrace) | D70: ='DAta 123'!E68 -> 241.59375 | E70: ='DAta 123'!F68 -> 259.5 | F70: ='DAta 123'!G68 -> 212.8125 | G70: ='DAta 123'!H68 -> 219.09375 | H70: ='DAta 123'!I68 -> 253.71875 | I70: ='DAta 123'!J68 -> 259.46875 | J70: ='DAta 123'!K68 -> 170.8125 | K70: ='DAta 123'!L68 -> 283.375 | ... AH70: ='DAta 123'!AI68 -> 0 | AK70: =Formulas_Past!AN70 -> 394.8878 | AL70: =Formulas_Past!AO70 -> 323.09002
... B79: =B78+1 -> 75 | C79: Outgoing To CELL Line SMSB-3 | D79: ='DAta 123'!E77 -> 2.9686559 | E79: ='DAta 123'!F77 -> 3.1995096 | F79: ='DAta 123'!G77 -> 3.3557174 | G79: ='DAta 123'!H77 -> 3.4493752 | H79: ='DAta 123'!I77 -> 3.1914292 | I79: ='DAta 123'!J77 -> 2.3981192 | J79: ='DAta 123'!K77 -> 3.2728373 | K79: ='DAta 123'!L77 -> 3.2759402 | ... AH79: ='DAta 123'!AI77 -> 0 | AK79: =Formulas_Past!AN79 -> 3.5910737 | AL79: =Formulas_Past!AO79 -> 2.9381512
...

Sheet Formulas_Past
B4: Sr. No. | C4: Locations | D4: =meta_sheet!A3 -> 46235 | E4: =D4+1 -> 46236 | F4: =E4+1 -> 46237 | G4: =F4+1 -> 46238 | H4: =G4+1 -> 46239 | I4: =H4+1 -> 46240 | J4: =I4+1 -> 46241 | K4: =J4+1 -> 46242 | L4: =K4+1 -> 46243 | ... AH4: =AG4+1 -> 46265 | AN4: ='123'!AO3 -> Red | AO4: ='123'!AP3 -> Yell
B5: 1 | C5: 66 KV CR Panel | D5: ='123'!E5 -> 64830.123 | E5: ='123'!F5 -> 58338.438 | F5: ='123'!G5 -> 65078.673 | G5: ='123'!H5 -> 64109.167 | H5: ='123'!I5 -> 64462.492 | I5: ='123'!J5 -> 65823.284 | J5: ='123'!K5 -> 67430.4 | K5: ='123'!L5 -> 69296.128 | ... AH5: ='123'!AI5 -> 68530.71 | AN5: ='123'!AO5 -> 74727.798 | AO5: ='123'!AP5 -> 61140.926
B6: =B5+1 -> 2 | C6: 11KV Incomer Breaker | D6: ='123'!E6 -> 64634.019 | E6: ='123'!F6 -> 58108.765 | F6: ='123'!G6 -> 64890.197 | G6: ='123'!H6 -> 63937.195 | H6: ='123'!I6 -> 64266.181 | I6: ='123'!J6 -> 65626.171 | J6: ='123'!K6 -> 67250.918 | K6: ='123'!L6 -> 69124.037 | ... AH6: ='123'!AI6 -> 68399.638 | AN6: ='123'!AO6 -> 74535.965 | AO6: ='123'!AP6 -> 60983.971
B7: =B6+1 -> 3 | C7: 11KV ATS O-G Breaker | D7: ='123'!E7 -> 43088.851 | E7: ='123'!F7 -> 39706.624 | F7: ='123'!G7 -> 43421.696 | G7: ='123'!H7 -> 42252.971 | H7: ='123'!I7 -> 42868.736 | I7: ='123'!J7 -> 43521.365 | J7: ='123'!K7 -> 44152.031 | K7: ='123'!L7 -> 45309.596 | ... AH7: ='123'!AI7 -> 44610.219 | AN7: ='123'!AO7 -> 48884.85 | AO7: ='123'!AP7 -> 39996.695
B8: =B7+1 -> 4 | C8: 11KV Module & Cell O-G Breaker | D8: ='123'!E8 -> 21960.021 | E8: ='123'!F8 -> 18783.915 | F8: ='123'!G8 -> 21889.365 | G8: ='123'!H8 -> 22093.141 | H8: ='123'!I8 -> 21827.584 | I8: ='123'!J8 -> 22540.614 | J8: ='123'!K8 -> 23552.356 | K8: ='123'!L8 -> 24265.387 | ... AH8: ='123'!AI8 -> 24234.028 | AN8: ='123'!AO8 -> 26133.62 | AO8: ='123'!AP8 -> 21382.053
B9: =B8+1 -> 5 | C9: Transformer - 1. OG Breaker | D9: ='123'!E9 -> 6235.5394 | E9: ='123'!F9 -> 4450.2537 | F9: ='123'!G9 -> 4632.7998 | G9: ='123'!H9 -> 5060.7816 | H9: ='123'!I9 -> 7358.4293 | I9: ='123'!J9 -> 7023.9805 | J9: ='123'!K9 -> 7515.2575 | K9: ='123'!L9 -> 6804.7056 | ... AH9: ='123'!AI9 -> 4816.5836 | AN9: ='123'!AO9 -> 6457.8416 | AO9: ='123'!AP9 -> 5283.6886
B10: =B9+1 -> 6 | C10: Transformer - 2. OG Breaker | D10: ='123'!E10 -> 11641.654 | E10: ='123'!F10 -> 10739.619 | F10: ='123'!G10 -> 9675.7586 | G10: ='123'!H10 -> 8006.4651 | H10: ='123'!I10 -> 5206.7797 | I10: ='123'!J10 -> 5384.435 | J10: ='123'!K10 -> 5668.3086 | K10: ='123'!L10 -> 8750.6875 | ... AH10: ='123'!AI10 -> 12073.411 | AN10: ='123'!AO10 -> 10866.439 | AO10: ='123'!AP10 -> 8890.7231
B11: =B10+1 -> 7 | C11: Transformer - 3. OG Breaker | D11: ='123'!E11 -> 8244.4843 | E11: ='123'!F11 -> 7806.9832 | F11: ='123'!G11 -> 8497.152 | G11: ='123'!H11 -> 8509.6411 | H11: ='123'!I11 -> 8567.027 | I11: ='123'!J11 -> 8925.67 | J11: ='123'!K11 -> 8985.3744 | K11: ='123'!L11 -> 8861.8696 | ... AH11: ='123'!AI11 -> 8589.5897 | AN11: ='123'!AO11 -> 9626.9399 | AO11: ='123'!AP11 -> 7876.5872
B12: =B11+1 -> 8 | C12: Transformer - 4. OG Breaker | D12: ='123'!E12 -> 8172.9779 | E12: ='123'!F12 -> 7874.7336 | F12: ='123'!G12 -> 7737.5523 | G12: ='123'!H12 -> 7776.499 | H12: ='123'!I12 -> 7644.8716 | I12: ='123'!J12 -> 7853.3511 | J12: ='123'!K12 -> 7927.8643 | K12: ='123'!L12 -> 7809.662 | ... AH12: ='123'!AI12 -> 8013.5347 | AN12: ='123'!AO12 -> 8666.1763 | AO12: ='123'!AP12 -> 7090.5079
B13: =B12+1 -> 9 | C13: Transformer - 5. OG Breaker | D13: ='123'!E13 -> 8648.3754 | E13: ='123'!F13 -> 8723.3621 | F13: ='123'!G13 -> 12726.578 | G13: ='123'!H13 -> 12815.407 | H13: ='123'!I13 -> 14020.49 | I13: ='123'!J13 -> 14118.648 | J13: ='123'!K13 -> 13924.838 | K13: ='123'!L13 -> 12944.748 | ... AH13: ='123'!AI13 -> 10948.608 | AN13: ='123'!AO13 -> 13448.27 | AO13: ='123'!AP13 -> 11003.13
B14: =B13+1 -> 10 | C14: 11KV DG Cummins-4 | D14: ='123'!E14 -> 0 | E14: ='123'!F14 -> 0 | F14: ='123'!G14 -> 0 | G14: ='123'!H14 -> 0 | H14: ='123'!I14 -> 0 | I14: ='123'!J14 -> 0 | J14: ='123'!K14 -> 0 | K14: ='123'!L14 -> 0 | ... AH14: ='123'!AI14 -> 0 | AN14: ='123'!AO14 -> 1710.016 | AO14: ='123'!AP14 -> 1399.104
B15: =B14+1 -> 11 | C15: 11KV DG, MTU-5 | D15: ='123'!E15 -> 0 | E15: ='123'!F15 -> 0 | F15: ='123'!G15 -> 0 | G15: ='123'!H15 -> 0 | H15: ='123'!I15 -> 0 | I15: ='123'!J15 -> 0.064 | J15: ='123'!K15 -> 0 | K15: ='123'!L15 -> 0 | ... AH15: ='123'!AI15 -> 0 | AN15: ='123'!AO15 -> 292.28672 | AO15: ='123'!AP15 -> 239.14368
B16: =B15+1 -> 12 | C16: 11KV DG, Cummins-6 | D16: ='123'!E16 -> 0 | E16: ='123'!F16 -> 0.192 | F16: ='123'!G16 -> 0 | G16: ='123'!H16 -> 0 | H16: ='123'!I16 -> 0 | I16: ='123'!J16 -> 0.192 | J16: ='123'!K16 -> 0 | K16: ='123'!L16 -> 0 | ... AH16: ='123'!AI16 -> 0 | AN16: ='123'!AO16 -> 485.4976 | AO16: ='123'!AP16 -> 397.22531
B17: =B16+1 -> 13 | C17: TOTAL HT DG | D17: =SUM(D14:D16) -> 0 | E17: =SUM(E14:E16) -> 0.192 | F17: =SUM(F14:F16) -> 0 | G17: =SUM(G14:G16) -> 0 | H17: =SUM(H14:H16) -> 0 | I17: =SUM(I14:I16) -> 0.256 | J17: =SUM(J14:J16) -> 0 | K17: =SUM(K14:K16) -> 0 | ... AH17: =SUM(AH14:AH16) -> 0 | AN17: =SUM(AN14:AN16) -> 2487.8003 | AO17: =SUM(AO14:AO16) -> 2035.473
B18: =B17+1 -> 14 | C18: Chiller - 4 | D18: ='123'!E17 -> 453.11637 | E18: ='123'!F17 -> 160.768 | F18: ='123'!G17 -> 414.72 | G18: ='123'!H17 -> 373.76 | H18: ='123'!I17 -> 924.52709 | I18: ='123'!J17 -> 715.21969 | J18: ='123'!K17 -> 834.95402 | K18: ='123'!L17 -> 897.62059 | ... AH18: ='123'!AI17 -> 539.91784 | AN18: ='123'!AO17 -> 831.19223 | AO18: ='123'!AP17 -> 680.06637
B19: =B18+1 -> 15 | C19: CDA - 2 | D19: ='123'!E18 -> 1953.3938 | E19: ='123'!F18 -> 405.64622 | F19: ='123'!G18 -> 0 | G19: ='123'!H18 -> 0 | H19: ='123'!I18 -> 0 | I19: ='123'!J18 -> 0 | J19: ='123'!K18 -> 0 | K19: ='123'!L18 -> 0 | ... AH19: ='123'!AI18 -> 0 | AN19: ='123'!AO18 -> 880.08448 | AO19: ='123'!AP18 -> 720.06912
B20: =B19+1 -> 16 | C20: CDA - 1 | D20: ='123'!E19 -> 2307.4521 | E20: ='123'!F19 -> 2307.4616 | F20: ='123'!G19 -> 2305.191 | G20: ='123'!H19 -> 2302.5363 | H20: ='123'!I19 -> 2301.2702 | I20: ='123'!J19 -> 2297.8087 | J20: ='123'!K19 -> 2299.4699 | K20: ='123'!L19 -> 2299.8595 | ... AH20: ='123'!AI19 -> 2288.1306 | AN20: ='123'!AO19 -> 2365.3486 | AO20: ='123'!AP19 -> 1935.2852
B21: =B20+1 -> 17 | C21: PMCC HVAC High Side | D21: ='123'!E20 -> 0.26799457 | E21: ='123'!F20 -> 0.27086737 | F21: ='123'!G20 -> 0.26649132 | G21: ='123'!H20 -> 0.26237024 | H21: ='123'!I20 -> 0.26187161 | I21: ='123'!J20 -> 0.26786764 | J21: ='123'!K20 -> 0.26773834 | K21: ='123'!L20 -> 0.26719973 | ... AH21: ='123'!AI20 -> 0.26798787 | AN21: ='123'!AO20 -> 0.29959568 | AO21: ='123'!AP20 -> 0.24512374
B22: =B21+1 -> 18 | C22: UPW Panel | D22: ='123'!E21 -> 0 | E22: ='123'!F21 -> 0 | F22: ='123'!G21 -> 0 | G22: ='123'!H21 -> 0 | H22: ='123'!I21 -> 0 | I22: ='123'!J21 -> 0 | J22: ='123'!K21 -> 0 | K22: ='123'!L21 -> 0 | ... AH22: ='123'!AI21 -> 0 | AN22: ='123'!AO21 -> 0 | AO22: ='123'!AP21 -> 0
B23: =B22+1 -> 19 | C23: Chiller - 3 | D23: ='123'!E22 -> 0 | E23: ='123'!F22 -> 0 | F23: ='123'!G22 -> 0 | G23: ='123'!H22 -> 0 | H23: ='123'!I22 -> 0 | I23: ='123'!J22 -> 0 | J23: ='123'!K22 -> 0 | K23: ='123'!L22 -> 0 | ... AH23: ='123'!AI22 -> 0 | AN23: ='123'!AO22 -> 0 | AO23: ='123'!AP22 -> 0
B24: =B23+1 -> 20 | C24: Chiller - 2 | D24: ='123'!E23 -> 0 | E24: ='123'!F23 -> 0 | F24: ='123'!G23 -> 0 | G24: ='123'!H23 -> 430.14678 | H24: ='123'!I23 -> 2482.0736 | I24: ='123'!J23 -> 2559.902 | J24: ='123'!K23 -> 2836.2908 | K24: ='123'!L23 -> 1682.7548 | ... AH24: ='123'!AI23 -> 0 | AN24: ='123'!AO23 -> 2130.6187 | AO24: ='123'!AP23 -> 1743.2335
B25: =B24+1 -> 21 | C25: Chiller - 1 | D25: ='123'!E24 -> 3675.8409 | E25: ='123'!F24 -> 3742.3578 | F25: ='123'!G24 -> 4182.9534 | G25: ='123'!H24 -> 2861.5481 | H25: ='123'!I24 -> 0 | I25: ='123'!J24 -> 0 | J25: ='123'!K24 -> 0 | K25: ='123'!L24 -> 1150.8587 | ... AH25: ='123'!AI24 -> 4300.2692 | AN25: ='123'!AO24 -> 3850.0935 | AO25: ='123'!AP24 -> 3150.0765
B26: =B25+1 -> 22 | C26: CDA - 3 | D26: ='123'!E25 -> 2231.1198 | E26: ='123'!F25 -> 2233.789 | F26: ='123'!G25 -> 272.26101 | G26: ='123'!H25 -> 0 | H26: ='123'!I25 -> 0 | I26: ='123'!J25 -> 0 | J26: ='123'!K25 -> 0 | K26: ='123'!L25 -> 1871.6944 | ... AH26: ='123'!AI25 -> 2230.0124 | AN26: ='123'!AO25 -> 2230.9357 | AO26: ='123'!AP25 -> 1825.311
B27: =B26+1 -> 23 | C27: Fire Pump | D27: ='123'!E26 -> 6.0039062 | E27: ='123'!F26 -> 2.5180664 | F27: ='123'!G26 -> 3.2939453 | G27: ='123'!H26 -> 3.6362305 | H27: ='123'!I26 -> 3.7006836 | I27: ='123'!J26 -> 3.465332 | J27: ='123'!K26 -> 3.6157227 | K27: ='123'!L26 -> 3.6210938 | ... AH27: ='123'!AI26 -> 1.1958008 | AN27: ='123'!AO26 -> 4.7832189 | AO27: ='123'!AP26 -> 3.9135427
B28: =B27+1 -> 24 | C28: 60KW Solar ( Above ATS) | D28: ='123'!E27 -> 338.8125 | E28: ='123'!F27 -> 398.9375 | F28: ='123'!G27 -> 322.15625 | G28: ='123'!H27 -> 305.8125 | H28: ='123'!I27 -> 460.75 | I28: ='123'!J27 -> 442 | J28: ='123'!K27 -> 354.375 | K28: ='123'!L27 -> 348.5625 | ... AH28: ='123'!AI27 -> 214.78125 | AN28: ='123'!AO27 -> 394.8878 | AO28: ='123'!AP27 -> 323.09002
B29: =B28+1 -> 25 | C29: CDA - 4 | D29: ='123'!E28 -> 2445.6848 | E29: ='123'!F28 -> 1724.5683 | F29: ='123'!G28 -> 1967.9086 | G29: ='123'!H28 -> 1938.7622 | H29: ='123'!I28 -> 2160.5428 | I29: ='123'!J28 -> 2297.7649 | J29: ='123'!K28 -> 2343.2203 | K29: ='123'!L28 -> 2366.1469 | ... AH29: ='123'!AI28 -> 2258.337 | AN29: ='123'!AO28 -> 2408.8216 | AO29: ='123'!AP28 -> 1970.8541
... B58: =B57+1 -> 54 | C58: Module UPS3 | D58: ='123'!E57 -> 57.578125 | E58: ='123'!F57 -> 75.03125 | F58: ='123'!G57 -> 58 | G58: ='123'!H57 -> 38.78125 | H58: ='123'!I57 -> 89.171875 | I58: ='123'!J57 -> 87.328125 | J58: ='123'!K57 -> 67.21875 | K58: ='123'!L57 -> 59.25 | ... AH58: ='123'!AI57 -> 62.109375 | AN58: ='123'!AO57 -> 82.846522 | AO58: ='123'!AP57 -> 67.783518
B59: =B58+1 -> 55 | C59: 20KW Solar (Above Canteen ) | D59: ='123'!E57 -> 57.578125 | E59: ='123'!F57 -> 75.03125 | F59: ='123'!G57 -> 58 | G59: ='123'!H57 -> 38.78125 | H59: ='123'!I57 -> 89.171875 | I59: ='123'!J57 -> 87.328125 | J59: ='123'!K57 -> 67.21875 | K59: ='123'!L57 -> 59.25 | ... AH59: ='123'!AI57 -> 62.109375 | AN59: ='123'!AO57 -> 82.846522 | AO59: ='123'!AP57 -> 67.783518
B60: =B59+1 -> 56 | C60: MV-2 SMSB | D60: ='123'!E58 -> 0 | E60: ='123'!F58 -> 0 | F60: ='123'!G58 -> 0 | G60: ='123'!H58 -> 0 | H60: ='123'!I58 -> 0 | I60: ='123'!J58 -> 0 | J60: ='123'!K58 -> 0 | K60: ='123'!L58 -> 0 | ... AH60: ='123'!AI58 -> 0 | AN60: ='123'!AO58 -> 0 | AO60: ='123'!AP58 -> 0
B61: =B60+1 -> 57 | C61: Unit 1 DG 1 - 365KVA | D61: ='123'!E59 -> 0 | E61: ='123'!F59 -> 0 | F61: ='123'!G59 -> 0 | G61: ='123'!H59 -> 137.10938 | H61: ='123'!I59 -> 0 | I61: ='123'!J59 -> 11.421875 | J61: ='123'!K59 -> 0 | K61: ='123'!L59 -> 0 | ... AH61: ='123'!AI59 -> 0 | AN61: ='123'!AO59 -> 66.642383 | AO61: ='123'!AP59 -> 54.525586
B62: =B61+1 -> 58 | C62: Unit 1 DG 2 - 380KVA | D62: ='123'!E60 -> 0 | E62: ='123'!F60 -> 0 | F62: ='123'!G60 -> 0 | G62: ='123'!H60 -> 0 | H62: ='123'!I60 -> 0 | I62: ='123'!J60 -> 0 | J62: ='123'!K60 -> 0 | K62: ='123'!L60 -> 0 | ... AH62: ='123'!AI60 -> 0 | AN62: ='123'!AO60 -> 0 | AO62: ='123'!AP60 -> 0
B63: =B62+1 -> 59 | C63: JINCHEN LAMINATOR 2 | D63: ='123'!E61 -> 877.10362 | E63: ='123'!F61 -> 882.27657 | F63: ='123'!G61 -> 889.45621 | G63: ='123'!H61 -> 890.3112 | H63: ='123'!I61 -> 910.4564 | I63: ='123'!J61 -> 895.8776 | J63: ='123'!K61 -> 899.0896 | K63: ='123'!L61 -> 891.314 | ... AH63: ='123'!AI61 -> 881.13455 | AN63: ='123'!AO61 -> 957.49246 | AO63: ='123'!AP61 -> 783.40293
B64: =B63+1 -> 60 | C64: Unit 1 EB Incomer | D64: ='123'!E62 -> 1951.9607 | E64: ='123'!F62 -> 2086.2924 | F64: ='123'!G62 -> 2044.1511 | G64: ='123'!H62 -> 1206.9292 | H64: ='123'!I62 -> 963.97083 | I64: ='123'!J62 -> 2011.3527 | J64: ='123'!K62 -> 2012.0147 | K64: ='123'!L62 -> 2025.7002 | ... AH64: ='123'!AI62 -> 1936.7939 | AN64: ='123'!AO62 -> 2004.1726 | AO64: ='123'!AP62 -> 1639.7776
B65: =B64+1 -> 61 | C65: Unit 5 EB Incomer | D65: ='123'!E63 -> 388.47344 | E65: ='123'!F63 -> 357.5779 | F65: ='123'!G63 -> 402.87992 | G65: ='123'!H63 -> 356.37466 | H65: ='123'!I63 -> 75.54878 | I65: ='123'!J63 -> 369.05 | J65: ='123'!K63 -> 378.15937 | K65: ='123'!L63 -> 403.90313 | ... AH65: ='123'!AI63 -> 343.54535 | AN65: ='123'!AO63 -> 381.82735 | AO65: ='123'!AP63 -> 312.4042
B66: =B65+1 -> 62 | C66: Unit 5 DG Incomer | D66: ='123'!E64 -> 0 | E66: ='123'!F64 -> 0 | F66: ='123'!G64 -> 0 | G66: ='123'!H64 -> 47.970703 | H66: ='123'!I64 -> 0 | I66: ='123'!J64 -> 0 | J66: ='123'!K64 -> 0.73046875 | K66: ='123'!L64 -> 0 | ... AH66: ='123'!AI64 -> 0 | AN66: ='123'!AO64 -> 8.9061328 | AO66: ='123'!AP64 -> 7.2868359
B67: =B66+1 -> 63 | C67: 90KW Solar (Above LT Room) | D67: ='123'!E65 -> 0 | E67: ='123'!F65 -> 0 | F67: ='123'!G65 -> 0 | G67: ='123'!H65 -> 0 | H67: ='123'!I65 -> 0 | I67: ='123'!J65 -> 0 | J67: ='123'!K65 -> 0 | K67: ='123'!L65 -> 0 | ... AH67: ='123'!AI65 -> 0 | AN67: ='123'!AO65 -> 0 | AO67: ='123'!AP65 -> 0
B68: =B67+1 -> 64 | C68: 120Kw Solar kit( chiller area 3to6) | D68: ='123'!E66 -> 453.76 | E68: ='123'!F66 -> 588.224 | F68: ='123'!G66 -> 456.512 | G68: ='123'!H66 -> 406.592 | H68: ='123'!I66 -> 697.472 | I68: ='123'!J66 -> 658.304 | J68: ='123'!K66 -> 516.672 | K68: ='123'!L66 -> 463.808 | ... AH68: ='123'!AI66 -> 476.755 | AN68: ='123'!AO66 -> 650.56692 | AO68: ='123'!AP66 -> 532.28203
B69: =B68+1 -> 65 | C69: 40 kW Solar (PECVD Pump Room) | D69: ='123'!E67 -> 24.46625 | E69: ='123'!F67 -> 31.206125 | F69: ='123'!G67 -> 23.747 | G69: ='123'!H67 -> 22.218875 | H69: ='123'!I67 -> 40.350625 | I69: ='123'!J67 -> 35.047875 | J69: ='123'!K67 -> 29.132375 | K69: ='123'!L67 -> 24.984125 | ... AH69: ='123'!AI67 -> 25.51125 | AN69: ='123'!AO67 -> 34.182008 | AO69: ='123'!AP67 -> 27.967097
B70: =B69+1 -> 66 | C70: 220Kw Solar(terrace) | D70: ='123'!E68 -> 338.8125 | E70: ='123'!F68 -> 398.9375 | F70: ='123'!G68 -> 322.15625 | G70: ='123'!H68 -> 305.8125 | H70: ='123'!I68 -> 460.75 | I70: ='123'!J68 -> 442 | J70: ='123'!K68 -> 354.375 | K70: ='123'!L68 -> 348.5625 | ... AH70: ='123'!AI68 -> 214.78125 | AN70: ='123'!AO68 -> 394.8878 | AO70: ='123'!AP68 -> 323.09002
... B79: =B78+1 -> 75 | C79: Outgoing To CELL Line SMSB-3 | D79: ='123'!E77 -> 2.6925835 | E79: ='123'!F77 -> 2.2018839 | F79: ='123'!G77 -> 3.015538 | G79: ='123'!H77 -> 2.8155598 | H79: ='123'!I77 -> 3.4010217 | I79: ='123'!J77 -> 3.3005556 | J79: ='123'!K77 -> 3.2980694 | K79: ='123'!L77 -> 3.4226672 | ... AH79: ='123'!AI77 -> 3.0314595 | AN79: ='123'!AO77 -> 3.5910737 | AO79: ='123'!AP77 -> 2.9381512

Sheet DAta 123
A1: kWh
B4: Sr. No. | C4: Locations | E4: 46235 | F4: 46236 | G4: 46237 | H4: 46238 | I4: 46239 | J4: 46240 | K4: 46241 | L4: 46242 | M4: 46243 | N4: 46244 | O4: 46245 | P4: 46246 | Q4: 46247 | R4: 46248 | S4: 46249 | T4: 46250 | U4: 46251 | V4: 46252 | W4: 46253 | X4: 46254 | Y4: 46255 | Z4: 46256 | AA4: 46257 | AB4: 46258 | AC4: 46259 | AD4: 46260 | AE4: 46261 | AF4: 46262 | AG4: 46263 | AH4: 46264 | AI4: 46265
B5: 1 | C5: 66 KV CR Panel | D5: 12744 | E5: 67760.811 | F5: 69006.198 | G5: 69183.967 | H5: 69125.461 | I5: 67790.106 | J5: 62611.515 | K5: 67102.037 | L5: 67291.225 | M5: 67336.103 | N5: 67889.835 | O5: 69159.595 | P5: 69251.072 | Q5: 70086.424 | R5: 67319.067 | S5: 67432.679 | T5: 67845.521 | U5: 67929.429
B6: 2 | C6: 11KV Incomer Breaker | D6: 11857 | E6: 67629.59 | F6: 68891.633 | G6: 69101.568 | H6: 69043.571 | I6: 67724.6 | J6: 62496.768 | K6: 66938.88 | L6: 67012.519 | M6: 67085.06 | N6: 67616.352 | O6: 68913.953 | P6: 68988.542 | Q6: 69840.926 | R6: 67066.835 | S6: 67258.724 | T6: 67698.688 | U6: 67781.291
B7: 3 | C7: 11KV ATS O-G Breaker | D7: 11858 | E7: 43807.403 | F7: 44806.827 | G7: 45115.897 | H7: 44830.898 | I7: 43341.824 | J7: 40592.384 | K7: 44196.864 | L7: 44222.464 | M7: 44047.73 | N7: 44549.432 | O7: 44534.443 | P7: 44526.963 | Q7: 45006.136 | R7: 42680.32 | S7: 44161.024 | T7: 44285.952 | U7: 44418.201
B8: 4 | C8: 11KV Module & Cell O-G Breaker | D8: 11859 | E8: 24271.146 | F8: 24525.141 | G8: 24434.005 | H8: 24642.219 | I8: 24818.05 | J8: 22311.09 | K8: 23171.873 | L8: 23233.536 | M8: 23466.325 | N8: 23487.147 | O8: 24838.827 | P8: 24909.765 | Q8: 25270.183 | R8: 24841.706 | S8: 23512.109 | T8: 23855.059 | U8: 23806.635
B9: 5 | C9: Transformer - 1. OG Breaker | D9: 11860 | E9: 5374.7851 | F9: 8070.5085 | G9: 8279.6127 | H9: 7685.4845 | I9: 8337.9287 | J9: 8758.7753 | K9: 9327.4598 | L9: 8875.9973 | M9: 9554.8225 | N9: 9912.9448 | O9: 9176.6535 | P9: 10319.057 | Q9: 8748.9519 | R9: 7798.4369 | S9: 6996.9746 | T9: 7512.7235 | U9: 7684.0613
B10: 6 | C10: Transformer - 2. OG Breaker | D10: 11861 | E10: 10382.215 | F10: 7540.1112 | G10: 7628.2099 | H10: 7683.8236 | I10: 7842.0644 | J10: 7114.8561 | K10: 7340.579 | L10: 7899.075 | M10: 7886.0843 | N10: 8043.0861 | O10: 7725.8891 | P10: 7851.4766 | Q10: 7862.3067 | R10: 7450.2769 | S10: 7804.6677 | T10: 7916.301 | U10: 7886.526
B11: 7 | C11: Transformer - 3. OG Breaker | D11: 11862 | E11: 8874.3089 | F11: 9107.8254 | G11: 9026.5635 | H11: 9012.6371 | I11: 8469.1395 | J11: 8449.7009 | K11: 9058.8941 | L11: 8975.3774 | M11: 8954.0343 | N11: 8976.9346 | O11: 8952.6064 | P11: 8882.4884 | Q11: 8811.8007 | R11: 8374.807 | S11: 8961.7356 | T11: 8871.9013 | U11: 8815.7028
B12: 8 | C12: Transformer - 4. OG Breaker | D12: 11863 | E12: 8031.9552 | F12: 8014.9001 | G12: 7963.5959 | H12: 7824.7485 | I12: 7862.9315 | J12: 7967.5184 | K12: 8062.4206 | L12: 7993.3093 | M12: 7998.7243 | N12: 7769.0706 | O12: 7924.0938 | P12: 7581.4877 | Q12: 7859.9463 | R12: 7845.9227 | S12: 7899.5178 | T12: 7872.7203 | U12: 7838.3902
B13: 9 | C13: Transformer - 5. OG Breaker | D13: 11864 | E13: 10985.541 | F13: 11920.991 | G13: 12090.214 | H13: 12437.779 | I13: 10653.522 | J13: 8140.4529 | K13: 10250.83 | L13: 10306.564 | M13: 9499.5068 | N13: 9707.3105 | O13: 10557.648 | P13: 9745.8766 | Q13: 11591.506 | R13: 11045.454 | S13: 12320.907 | T13: 11969.415 | U13: 12021.934
B14: 10 | C14: 11KV DG Cummins-4 | D14: 11865 | E14: 0 | F14: 0 | G14: 0 | H14: 0 | I14: 0 | J14: 0 | K14: 0 | L14: 0 | M14: 0 | N14: 0 | O14: 0 | P14: 0 | Q14: 0 | R14: 0 | S14: 0 | T14: 0 | U14: 0
B15: 11 | C15: 11KV DG, MTU-5 | D15: 11866 | E15: 0 | F15: 0 | G15: 0 | H15: 0 | I15: 0 | J15: 0.064 | K15: 0 | L15: 0 | M15: 0 | N15: 0 | O15: 0 | P15: 0 | Q15: 0.064 | R15: 0 | S15: 0 | T15: 0 | U15: 0.064
B16: 12 | C16: 11KV DG, Cummins-6 | D16: 11867 | E16: 0 | F16: 0 | G16: 0.192 | H16: 0 | I16: 0 | J16: 0.192 | K16: 0 | L16: 0 | M16: 0 | N16: 0.192 | O16: 0 | P16: 0 | Q16: 0.128 | R16: 0 | S16: 0 | T16: 0 | U16: 0.192
... B78: 74 | C78: Outgoing To CDA 6,7,8 | D78: 35157 | E78: 2349.7204 | F78: 2325.6129 | G78: 2320.087 | H78: 2352.2141 | I78: 1409.6989 | J78: 498 | K78: 1036 | L78: 981 | M78: 200 | N78: 44 | O78: 1289 | P78: 50 | Q78: 1730.6774 | R78: 2310.3548 | S78: 3240.4516 | T78: 2473.777 | U78: 2370.9972

Sheet 123
A1: kWh
AO3: Red | AP3: Yell
B4: Sr. No. | C4: Locations | E4: 46204 | F4: 46205 | G4: 46206 | H4: 46207 | I4: 46208 | J4: 46209 | K4: 46210 | L4: 46211 | M4: 46212 | N4: 46213 | O4: 46214 | P4: 46215 | Q4: 46216 | R4: 46217 | S4: 46218 | T4: 46219 | U4: 46220 | V4: 46221 | W4: 46222 | X4: 46223 | Y4: 46224 | Z4: 46225 | AA4: 46226 | AB4: 46227 | AC4: 46228 | AD4: 46229 | AE4: 46230 | AF4: 46231 | AG4: 46232 | AH4: 46233 | AI4: 46234 | AM4: 0.1 | AO4: + | AP4: -
B5: 1 | C5: 66 KV CR Panel | D5: 12744 | E5: 64830.123 | F5: 58338.438 | G5: 65078.673 | H5: 64109.167 | I5: 64462.492 | J5: 65823.284 | K5: 67430.4 | L5: 69296.128 | M5: 70765.227 | N5: 70045.013 | O5: 70322.176 | P5: 69434.917 | Q5: 69894.856 | R5: 70794.739 | S5: 69714.89 | T5: 67414.699 | U5: 68349.269 | V5: 57024.69 | W5: 69809.998 | X5: 68072.047 | Y5: 70168.635 | Z5: 70299.945 | AA5: 69114.925 | AB5: 69603.328 | AC5: 66036.395 | AD5: 70463.072 | AE5: 70456.186 | AF5: 72107.409 | AG5: 69798.719 | AH5: 68374.676 | AI5: 68530.71 | AL5: 67934.362 | AM5: 6793.4362 | AO5: 74727.798 | AP5: 61140.926
B6: 2 | C6: 11KV Incomer Breaker | D6: 11857 | E6: 64634.019 | F6: 58108.765 | G6: 64890.197 | H6: 63937.195 | I6: 64266.181 | J6: 65626.171 | K6: 67250.918 | L6: 69124.037 | M6: 70560.427 | N6: 69831.992 | O6: 70124.945 | P6: 69238.754 | Q6: 69711.872 | R6: 70619.543 | S6: 69531.983 | T6: 67234.415 | U6: 68156.656 | V6: 56871.607 | W6: 69696.942 | X6: 67973.803 | Y6: 70086.923 | Z6: 70201.76 | AA6: 69000.266 | AB6: 69488.224 | AC6: 65856.171 | AD6: 70217.728 | AE6: 70226.603 | AF6: 71886.165 | AG6: 69591.911 | AH6: 68213.2 | AI6: 68399.638 | AL6: 67759.968 | AM6: 6775.9968 | AO6: 74535.965 | AP6: 60983.971
B7: 3 | C7: 11KV ATS O-G Breaker | D7: 11858 | E7: 43088.851 | F7: 39706.624 | G7: 43421.696 | H7: 42252.971 | I7: 42868.736 | J7: 43521.365 | K7: 44152.031 | L7: 45309.596 | M7: 46222.47 | N7: 45976.917 | O7: 45795.209 | P7: 44989.9 | Q7: 45742.08 | R7: 46699.149 | S7: 45643.806 | T7: 43682.475 | U7: 44552.192 | V7: 37230.592 | W7: 45481.717 | X7: 44445.963 | Y7: 45216.427 | Z7: 45903.872 | AA7: 44457.301 | AB7: 44895.573 | AC7: 42918.66 | AD7: 46051.239 | AE7: 46060.203 | AF7: 47265.109 | AG7: 45292.885 | AH7: 44208.128 | AI7: 44610.219 | AL7: 44440.773 | AM7: 4444.0773 | AO7: 48884.85 | AP7: 39996.695
B8: 4 | C8: 11KV Module & Cell O-G Breaker | D8: 11859 | E8: 21960.021 | F8: 18783.915 | G8: 21889.365 | H8: 22093.141 | I8: 21827.584 | J8: 22540.614 | K8: 23552.356 | L8: 24265.387 | M8: 24780.117 | N8: 24305.664 | O8: 24777.387 | P8: 24706.731 | Q8: 24419.476 | R8: 24370.039 | S8: 24319.647 | T8: 23988.268 | U8: 24033.236 | V8: 19999.744 | W8: 24657.697 | X8: 23968.011 | Y8: 25311.499 | Z8: 24754.206 | AA8: 24997.547 | AB8: 25052.961 | AC8: 23368.214 | AD8: 24630.984 | AE8: 24627.541 | AF8: 25076.395 | AG8: 24749.739 | AH8: 24451.413 | AI8: 24234.028 | AL8: 23757.836 | AM8: 2375.7836 | AO8: 26133.62 | AP8: 21382.053
B9: 5 | C9: Transformer - 1. OG Breaker | D9: 11860 | E9: 6235.5394 | F9: 4450.2537 | G9: 4632.7998 | H9: 5060.7816 | I9: 7358.4293 | J9: 7023.9805 | K9: 7515.2575 | L9: 6804.7056 | M9: 5830.1353 | N9: 6468.4171 | O9: 7540.493 | P9: 9071.9553 | Q9: 7975.1801 | R9: 5571.6074 | S9: 4366.9895 | T9: 4530.3148 | U9: 4717.3424 | V9: 5401.3049 | W9: 7389.2211 | X9: 5646.7187 | Y9: 4411.0695 | Z9: 5058.5322 | AA9: 4994.5166 | AB9: 4342.2994 | AC9: 3907.5653 | AD9: 6199.296 | AE9: 7495.7147 | AF9: 6548.0461 | AG9: 4872.2267 | AH9: 5756.442 | AI9: 4816.5836 | AL9: 5870.7651 | AM9: 587.07651 | AO9: 6457.8416 | AP9: 5283.6886
B10: 6 | C10: Transformer - 2. OG Breaker | D10: 11861 | E10: 11641.654 | F10: 10739.619 | G10: 9675.7586 | H10: 8006.4651 | I10: 5206.7797 | J10: 5384.435 | K10: 5668.3086 | L10: 8750.6875 | M10: 10653.892 | N10: 8961.1922 | O10: 7708.3273 | P10: 5064.6669 | Q10: 8499.6165 | R10: 11953.471 | S10: 13054.275 | T10: 12007.563 | U10: 11929.288 | V10: 10574.414 | W10: 8596.5321 | X10: 10342.594 | Y10: 11860.002 | Z10: 11279.305 | AA10: 11246.661 | AB10: 10905.461 | AC10: 10145.539 | AD10: 8036.7087 | AE10: 9821.0278 | AF10: 12674.933 | AG10: 12132.144 | AH10: 11641.283 | AI10: 12073.411 | AL10: 9878.5812 | AM10: 987.85812 | AO10: 10866.439 | AP10: 8890.7231
B11: 7 | C11: Transformer - 3. OG Breaker | D11: 11862 | E11: 8244.4843 | F11: 7806.9832 | G11: 8497.152 | H11: 8509.6411 | I11: 8567.027 | J11: 8925.67 | K11: 8985.3744 | L11: 8861.8696 | M11: 8943.0953 | N11: 8733.5051 | O11: 8688.7962 | P11: 8685.4926 | Q11: 8812.8277 | R11: 8769.3208 | S11: 8879.9961 | T11: 8286.3421 | U11: 8598.8278 | V11: 8790.2243 | W11: 9115.6827 | X11: 8753.7122 | Y11: 9075.4181 | Z11: 9159.563 | AA11: 8554.2177 | AB11: 8812.7425 | AC11: 9053.965 | AD11: 9091.3736 | AE11: 9050.0186 | AF11: 9067.0861 | AG11: 8824.3113 | AH11: 8570.3593 | AI11: 8589.5897 | AL11: 8751.7635 | AM11: 875.17635 | AO11: 9626.9399 | AP11: 7876.5872
B12: 8 | C12: Transformer - 4. OG Breaker | D12: 11863 | E12: 8172.9779 | F12: 7874.7336 | G12: 7737.5523 | H12: 7776.499 | I12: 7644.8716 | J12: 7853.3511 | K12: 7927.8643 | L12: 7809.662 | M12: 7891.7184 | N12: 7736.8125 | O12: 7918.7482 | P12: 7900.3509 | Q12: 7836.4117 | R12: 7810.4872 | S12: 7985.257 | T12: 8034.8532 | U12: 8061.8999 | V12: 7986.1515 | W12: 8011.436 | X12: 8028.4108 | Y12: 8027.0184 | Z12: 8004.6137 | AA12: 7640.4285 | AB12: 7481.9341 | AC12: 7783.6158 | AD12: 7927.5294 | AE12: 7879.7321 | AF12: 7920.1367 | AG12: 7836.5505 | AH12: 7713.4622 | AI12: 8013.5347 | AL12: 7878.3421 | AM12: 787.83421 | AO12: 8666.1763 | AP12: 7090.5079
B13: 9 | C13: Transformer - 5. OG Breaker | D13: 11864 | E13: 8648.3754 | F13: 8723.3621 | G13: 12726.578 | H13: 12815.407 | I13: 14020.49 | J13: 14118.648 | K13: 13924.838 | L13: 12944.748 | M13: 12749.807 | N13: 13926.886 | O13: 13802.965 | P13: 14116.682 | Q13: 12530.229 | R13: 12380.505 | S13: 11259.558 | T13: 10646.282 | U13: 11090.357 | V13: 11259.14 | W13: 12210.419 | X13: 11531.221 | Y13: 11686.29 | Z13: 12243.887 | AA13: 11897.63 | AB13: 13196.375 | AC13: 14645.526 | AD13: 14626.538 | AE13: 11638.715 | AF13: 10884.773 | AG13: 11449.465 | AH13: 10352.397 | AI13: 10948.608 | AL13: 12225.7 | AM13: 1222.57 | AO13: 13448.27 | AP13: 11003.13
B14: 10 | C14: 11KV DG Cummins-4 | D14: 11865 | E14: 0 | F14: 0 | G14: 0 | H14: 0 | I14: 0 | J14: 0 | K14: 0 | L14: 0 | M14: 0 | N14: 0 | O14: 0 | P14: 0 | Q14: 0 | R14: 0 | S14: 0 | T14: 0 | U14: 0 | V14: 2240.256 | W14: 0 | X14: 0 | Y14: 0 | Z14: 0 | AA14: 0 | AB14: 0 | AC14: 868.864 | AD14: 0 | AE14: 0 | AF14: 0 | AG14: 0 | AH14: 0 | AI14: 0 | AL14: 1554.56 | AM14: 155.456 | AO14: 1710.016 | AP14: 1399.104
