Workbook

Sheet Formulas_Overview
B3: From: | C3: =meta_sheet!A3 -> 46235 | E3: To: | F3: =meta_sheet!A4-1 -> 46251
B4: Locations | E4: Daily | F4: MTD
B5: UNIT :- 1
C6: Unit 1 EB Incomer | D6: 12819 | E6: =HLOOKUP($D6,'Monthly report'!$O$4:$U$5,2,0) -> 1870.3953 | F6: =HLOOKUP($D6,'Monthly report'!$B$6:$F$39,34,0) -> 27153.95
C7: Unit 1 DG 1 - 365KVA | D7: 12817 | E7: =HLOOKUP($D7,'Monthly report'!$O$4:$U$5,2,0) -> 0 | F7: =HLOOKUP($D7,'Monthly report'!$B$6:$F$39,34,0) -> 847.39844
C8: Unit 1 DG 2 - 380KVA | D8: 12818 | E8: =HLOOKUP($D8,'Monthly report'!$O$4:$U$5,2,0) -> 0 | F8: =HLOOKUP($D8,'Monthly report'!$B$6:$F$39,34,0) -> 0
B9: Total | E9: =E6+E7+E8 -> 1870.3953 | F9: =F6+F7+F8 -> 28001.348
B10: UNIT :- 5
C11: Unit 5 EB Incomer | D11: 13578 | E11: =HLOOKUP($D11,'Monthly report'!$O$4:$U$5,2,0) -> 503.89844 | F11: =HLOOKUP($D11,'Monthly report'!$B$6:$F$39,34,0) -> 5866.2312
C12: Unit 5 DG Incomer | D12: 13579 | E12: =HLOOKUP($D12,'Monthly report'!$O$4:$U$5,2,0) -> 0 | F12: =HLOOKUP($D12,'Monthly report'!$B$6:$F$39,34,0) -> 161.58398
B13: Total | E13: =E11+E12 -> 503.89844 | F13: =F11+F12 -> 6027.8152

Sheet Formulas_Consumption Summary
B2: UNIT :- 1 | H2: UNIT :- 5
B4: From: | D4: =Formulas_Overview!C3 -> 46235 | E4: To: | F4: =Formulas_Overview!F3 -> 46251 | H4: From | I4: =D4 -> 46235 | J4: =D4 -> 46235 | K4: To | L4: =F4 -> 46251
B5: Locations - Manufacturing | E5: Daily | F5: MTD | H5: Locations - Manufacturing | K5: Daily | L5: MTD
B6: Import energy from EB | H6: Import energy from EB
B7: Unit 1 EB Incomer | C7: 12819 | E7: =Formulas_Overview!E6 -> 1870.3953 | F7: =Formulas_Overview!F6 -> 27153.95 | H7: Unit 5 EB Incomer | I7: 13578 | K7: =Formulas_Overview!E11 -> 503.89844 | L7: =Formulas_Overview!F11 -> 5866.2312
B8: MD Recorded | E8: =VLOOKUP(F4,'PF & Demand'!K7:L37,2,0) -> 125.4683 | F8: =MAX('PF & Demand'!L7:L37) -> 139.75594 | H8: MD Recorded | K8: =VLOOKUP(L4,'PF & Demand'!K7:M37,3,0) -> 47.37132 | L8: =MAX('PF & Demand'!M7:M37) -> 49.015617
B9: PF | E9: =VLOOKUP(F4,'PF & Demand'!$K$7:$P$37,6,0) -> 0.86724488 | F9: =IFERROR(AVERAGEIF('PF & Demand'!P6:P37,">0",'PF & Demand'!P6:P37),"-") -> 0.81758905 | H9: PF | K9: =VLOOKUP(L4,'PF & Demand'!K7:Q37,7,0) -> 0.65485071 | L9: =MAX('PF & Demand'!Q7:Q37) -> 0.87893275
B10: Captive Generation DG | E10: 0 | F10: =SUM(F11:F12) -> 847.39844 | H10: Captive Generation DG
B11: Unit 1 DG 1 - 365KVA | C11: 12817 | E11: =Formulas_Overview!E7 -> 0 | F11: =Formulas_Overview!F7 -> 847.39844 | H11: Unit 5 DG Incomer | I11: 13579 | K11: =Formulas_Overview!E12 -> 0 | L11: =Formulas_Overview!F12 -> 161.58398
B12: Unit 1 DG 2 - 380KVA | C12: 12818 | E12: =Formulas_Overview!E8 -> 0 | F12: =Formulas_Overview!F8 -> 0

Sheet PF & Demand
A1: pf | B1: 60 | F1: kva
B4: pf | G4: Demand
B5: Unit 1 EB Incomer | C5: Unit 5 EB Incomer | G5: Unit 1 EB Incomer | H5: Unit 5 EB Incomer | L5: Demand | P5: pf
B6: 12819 | C6: 13578 | G6: 12819 | H6: 13578 | L6: Unit 1 EB Incomer | M6: Unit 5 EB Incomer | P6: Unit 1 EB Incomer | Q6: Unit 5 EB Incomer
A7: 46235.25 | B7: 0.84851122 | C7: 0.57982099 | F7: 46235.25 | G7: 62.20738 | H7: 26.509625 | K7: 46235 | L7: 112.0532 | M7: 42.657796 | P7: 0.84783442 | Q7: 0.5935976
A8: 46235.292 | B8: 0.88244205 | C8: 0.80088747 | F8: 46235.292 | G8: 73.301853 | H8: 34.588595 | K8: 46236 | L8: 76.295999 | M8: 23.708432 | P8: 0.77261555 | Q8: 0.1821207
A9: 46235.333 | B9: 0.89515676 | C9: 0.45337941 | F9: 46235.333 | G9: 76.345453 | H9: 24.859421 | K9: 46237 | L9: 123.18908 | M9: 40.136758 | P9: 0.87607034 | Q9: 0.58194994
A10: 46235.375 | B10: 0.88473322 | C10: 0.43602632 | F10: 46235.375 | G10: 73.100614 | H10: 26.084224 | K10: 46238 | L10: 129.09012 | M10: 38.796131 | P10: 0.87294766 | Q10: 0.60167714
A11: 46235.417 | B11: 0.88897634 | C11: 0.35521082 | F11: 46235.417 | G11: 75.138669 | H11: 23.385891 | K11: 46239 | L11: 122.94877 | M11: 32.979512 | P11: 0.8560166 | Q11: 0.57748045
A12: 46235.458 | B12: 0.91191457 | C12: 0.41247755 | F12: 46235.458 | G12: 78.96897 | H12: 24.327397 | K12: 46240 | L12: 127.12432 | M12: 38.033063 | P12: 0.87955679 | Q12: 0.57283868
A13: 46235.5 | B13: 0.9385188 | C13: 0.44203691 | F13: 46235.5 | G13: 112.0532 | H13: 23.931034 | K13: 46241 | L13: 129.96989 | M13: 38.343733 | P13: 0.86841196 | Q13: 0.57657177
A14: 46235.542 | B14: 0.93473974 | C14: 0.46419891 | F14: 46235.542 | G14: 103.72417 | H14: 25.202935 | K14: 46242 | L14: 78.5582 | M14: 42.408224 | P14: 0.76037314 | Q14: 0.55593355
A15: 46235.583 | B15: 0.94230536 | C15: 0.42627761 | F15: 46235.583 | G15: 109.33861 | H15: 24.320943 | K15: 46243 | L15: 60.146387 | M15: 24.165906 | P15: 0.74644521 | Q15: 0.16378728
A16: 46235.625 | B16: 0.93293921 | C16: 0.31628385 | F16: 46235.625 | G16: 106.36912 | H16: 23.849785 | K16: 46244 | L16: 136.17964 | M16: 47.546789 | P16: 0.88424689 | Q16: 0.6035864
A17: 46235.667 | B17: 0.90844244 | C17: 0.47619573 | F17: 46235.667 | G17: 96.298439 | H17: 25.597197 | K17: 46245 | L17: 139.60378 | M17: 45.186539 | P17: 0.89309465 | Q17: 0.60768106
A18: 46235.708 | B18: 0.90704153 | C18: 0.57919087 | F18: 46235.708 | G18: 96.822976 | H18: 24.183489 | K18: 46246 | L18: 139.75594 | M18: 40.521268 | P18: 0.80730729 | Q18: 0.62115087
... A26: 46236.042 | B26: 0.74876044 | C26: 0.65838269 | F26: 46236.042 | G26: 55.316936 | H26: 28.998573 | K26: 46254 | L26: 43.285339 | M26: 12.375701 | P26: 0.48514365 | Q26: 0.7085141
A27: 46236.083 | B27: 0.74198114 | C27: 0.77568577 | F27: 46236.083 | G27: 55.865615 | H27: 34.287371 | K27: 46255 | L27: 0 | M27: 0 | P27: - | Q27: -
A28: 46236.125 | B28: 0.73551853 | C28: 0.71771831 | F28: 46236.125 | G28: 53.396048 | H28: 31.827394 | K28: 46256 | L28: 0 | M28: 0 | P28: - | Q28: -
A29: 46236.167 | B29: 0.73340651 | C29: 0.61218924 | F29: 46236.167 | G29: 52.864373 | H29: 25.693152 | K29: 46257 | L29: 0 | M29: 0 | P29: - | Q29: -
A30: 46236.208 | B30: 0.75085897 | C30: 0.52309584 | F30: 46236.208 | G30: 52.456553 | H30: 25.472606 | K30: 46258 | L30: 0 | M30: 0 | P30: - | Q30: -
A31: 46236.25 | B31: 0.76990928 | C31: 0.14237905 | F31: 46236.25 | G31: 52.213048 | H31: 22.616057 | K31: 46259 | L31: 0 | M31: 0 | P31: - | Q31: -
A32: 46236.292 | B32: 0.7769955 | C32: 0.12255486 | F32: 46236.292 | G32: 53.307748 | H32: 22.410185 | K32: 46260 | L32: 0 | M32: 0 | P32: - | Q32: -
A33: 46236.333 | B33: 0.79062606 | C33: 0.11903468 | F33: 46236.333 | G33: 53.58689 | H33: 22.386843 | K33: 46261 | L33: 0 | M33: 0 | P33: - | Q33: -
A34: 46236.375 | B34: 0.76947474 | C34: 0.13279549 | F34: 46236.375 | G34: 52.830307 | H34: 22.203016 | K34: 46262 | L34: 0 | M34: 0 | P34: - | Q34: -
A35: 46236.417 | B35: 0.72652219 | C35: 0.11964608 | F35: 46236.417 | G35: 50.81782 | H35: 22.380436 | K35: 46263 | L35: 0 | M35: 0 | P35: - | Q35: -
A36: 46236.458 | B36: 0.78851298 | C36: 0.12995013 | F36: 46236.458 | G36: 58.129557 | H36: 19.67 | K36: 46264 | L36: 0 | M36: 0 | P36: - | Q36: -
A37: 46236.5 | B37: 0.72794369 | C37: 0.15081356 | F37: 46236.5 | G37: 51.987045 | H37: 22.265797 | K37: 46265 | L37: 0 | M37: 0 | P37: - | Q37: -
A38: 46236.542 | B38: 0.77363011 | C38: 0.15366532 | F38: 46236.542 | G38: 56.227273 | H38: 22.387551
A39: 46236.583 | B39: 0.751499 | C39: 0.17181209 | F39: 46236.583 | G39: 54.254706 | H39: 22.051898
A40: 46236.625 | B40: 0.77733403 | C40: 0.15279333 | F40: 46236.625 | G40: 58.360309 | H40: 22.447509
A41: 46236.667 | B41: 0.78938741 | C41: 0.16201074 | F41: 46236.667 | G41: 58.600137 | H41: 22.303379
A42: 46236.708 | B42: 0.84787005 | C42: 0.16232612 | F42: 46236.708 | G42: 76.295999 | H42: 22.179263
A43: 46236.75 | B43: 0.85558548 | C43: 0.17428648 | F43: 46236.75 | G43: 75.824653 | H43: 22.278196
A44: 46236.792 | B44: 0.80948998 | C44: 0.23543907 | F44: 46236.792 | G44: 60.510063 | H44: 23.170706
A45: 46236.833 | B45: 0.7925241 | C45: 0.23238824 | F45: 46236.833 | G45: 57.595721 | H45: 23.317925
A46: 46236.875 | B46: 0 | C46: 0.23189203 | F46: 46236.875 | G46: 0 | H46: 23.33143
A47: 46236.917 | B47: 0 | C47: 0.22434942 | F47: 46236.917 | G47: 0 | H47: 23.47269
A48: 46236.958 | B48: 0 | C48: 0.22608582 | F48: 46236.958 | G48: 0 | H48: 23.418884
A49: 46237 | B49: 0.69318467 | C49: 0.22458032 | F49: 46237 | G49: 47.83481 | H49: 23.253348
...

Sheet Formulas_Carbon Footprint
B4: Locations - Manufacturing | D4: Daily | E4: MTD | N4: Daily | O4: MTD
B5: Import energy from EB | L5: Import energy from EB
B6: Unit 1 EB Incomer | D6: ='Formulas_Consumption Summary'!E7 -> 1870.3953 | E6: ='Formulas_Consumption Summary'!F7 -> 27153.95 | L6: Unit 5 EB Incomer | N6: ='Formulas_Consumption Summary'!K7 -> 503.89844 | O6: ='Formulas_Consumption Summary'!L7 -> 5866.2312
B7: Carbon Emission 1 | D7: =D6*2.72 -> 5087.4752 | E7: =E6*2.72 -> 73858.744 | L7: Carbon Emission 1 | N7: =N6*2.72 -> 1370.6037 | O7: =O6*2.72 -> 15956.149
B8: Captive Generation DG | D8: ='Formulas_Consumption Summary'!D9 -> 0 | E8: =SUM(E9:E10) -> 847.39844 | L8: Captive Generation DG | N8: ='Formulas_Consumption Summary'!J8 -> 0 | O8: ='Formulas_Consumption Summary'!K8 -> 47.37132
B9: Unit 1 DG 1 - 365KVA | D9: ='Formulas_Consumption Summary'!E11 -> 0 | E9: ='Formulas_Consumption Summary'!F11 -> 847.39844 | L9: Unit 5 DG Incomer | N9: ='Formulas_Consumption Summary'!K11 -> 0 | O9: ='Formulas_Consumption Summary'!L11 -> 161.58398
B10: Unit 1 DG 2 - 380KVA | D10: ='Formulas_Consumption Summary'!E12 -> 0 | E10: ='Formulas_Consumption Summary'!F12 -> 0
B11: Carbon Emission 2 | D11: =D8*2.72 -> 0 | E11: =E7*2.72 -> 200895.78 | L11: Carbon Emission 2 | N11: =N8*2.72 -> 0 | O11: =O8*2.72 -> 128.84999
B12: Generation Solar Roof top | D12: ='Formulas_Consumption Summary'!D15 -> 0 | E12: ='Formulas_Consumption Summary'!E15 -> 0 | L12: Generation Solar Roof top
B13: Net Carbon Emission | D13: =D7+D11 -> 5087.4752 | E13: =E7+E11 -> 274754.53 | L13: Net Carbon Emission | N13: =N7+N9 -> 1370.6037 | O13: =O7+O9 -> 16117.733

Sheet  Formulas_TODwise Consumption R
B3: Locations | D3: Time | E3: 46235 | F3: 46236 | G3: 46237 | H3: 46238 | I3: 46239 | J3: 46240 | K3: 46241 | L3: 46242 | M3: 46243 | N3: 46244 | O3: 46245 | P3: 46246 | Q3: 46247 | R3: 46248 | S3: 46249 | T3: 46250 | U3: 46251 | V3: 46252 | W3: 46253 | X3: 46254 | Y3: 46255 | Z3: 46256 | AA3: 46257 | AB3: 46258 | AC3: 46259 | AD3: 46260 | AE3: 46261 | AF3: 46262 | AG3: 46263 | AH3: 46264 | AI3: 46265 | AJ3: Total | AK3: Total (%)
B4: Unit 1 EB Incomer | C4: Unit 1 EB Incomer06:00 to 10:00 | D4: 06:00 to 10:00 | E4: 250.275 | F4: 165.48416 | G4: 360.76242 | H4: 373.74167 | I4: 361.775 | J4: 342.67917 | K4: 368 | L4: 240.94549 | M4: 154.31667 | N4: 343.08852 | O4: 363.04857 | P4: 368.1875 | Q4: 371.28333 | R4: 393 | S4: 199.38333 | T4: 152.5 | U4: 356.58695 | V4: 0 | W4: 0 | X4: 0 | Y4: 0 | Z4: 0 | AA4: 0 | AB4: 0 | AC4: 0 | AD4: 0 | AE4: 0 | AF4: 0 | AG4: 0 | AH4: 0 | AI4: 0 | AJ4: 5165.0578 | AK4: 0.19021387
C5: Unit 1 EB Incomer10:00 to 18:00 | D5: 10:00 to 18:00 | E5: 719.49693 | F5: 362.30272 | G5: 888.82759 | H5: 916.78333 | I5: 889.7625 | J5: 880.53333 | K5: 861.125 | L5: 416.60637 | M5: 305.19583 | N5: 936.4 | O5: 1010.0598 | P5: 491.03333 | Q5: 967.8 | R5: 947.7776 | S5: 325.57213 | T5: 315.825 | U5: 912.74583 | V5: 0 | W5: 0 | X5: 0 | Y5: 0 | Z5: 0 | AA5: 0 | AB5: 0 | AC5: 0 | AD5: 0 | AE5: 0 | AF5: 0 | AG5: 0 | AH5: 0 | AI5: 0 | AJ5: 12147.847 | AK5: 0.44736943
C6: Unit 1 EB Incomer18:00 to 22:00 | D6: 18:00 to 22:00 | E6: 217.81557 | F6: 125.2765 | G6: 279.48966 | H6: 274.775 | I6: 223.9625 | J6: 304.3 | K6: 261.47952 | L6: 123.93564 | M6: 189.0125 | N6: 298.9875 | O6: 300.24167 | P6: 333.77917 | Q6: 284.925 | R6: 273.68074 | S6: 191.85287 | T6: 187.2875 | U6: 265.775 | V6: 0 | W6: 0 | X6: 0 | Y6: 0 | Z6: 0 | AA6: 0 | AB6: 0 | AC6: 0 | AD6: 0 | AE6: 0 | AF6: 0 | AG6: 0 | AH6: 0 | AI6: 0 | AJ6: 4136.5763 | AK6: 0.15233792
C7: Unit 1 EB Incomer22:00 to 06:00 | D7: 22:00 to 06:00 | E7: 335.03279 | F7: 215.37416 | G7: 362.525 | H7: 343.5125 | I7: 338 | J7: 374.76667 | K7: 342.80381 | L7: 321.9875 | M7: 316.48648 | N7: 344 | O7: 373.475 | P7: 337.72917 | Q7: 340.71667 | R7: 334.94167 | S7: 342.025 | T7: 345.80471 | U7: 335.2875 | V7: 0 | W7: 0 | X7: 0 | Y7: 0 | Z7: 0 | AA7: 0 | AB7: 0 | AC7: 0 | AD7: 0 | AE7: 0 | AF7: 0 | AG7: 0 | AH7: 0 | AI7: 0 | AJ7: 5704.4686 | AK7: 0.21007878
D8: Total | E8: 1522.6203 | F8: 868.43755 | G8: 1891.6047 | H8: 1908.8125 | I8: 1813.5 | J8: 1902.2792 | K8: 1833.4083 | L8: 1103.475 | M8: 965.01148 | N8: 1922.476 | O8: 2046.825 | P8: 1530.7292 | Q8: 1964.725 | R8: 1949.4 | S8: 1058.8333 | T8: 1001.4172 | U8: 1870.3953 | V8: 0 | W8: 0 | X8: 0 | Y8: 0 | Z8: 0 | AA8: 0 | AB8: 0 | AC8: 0 | AD8: 0 | AE8: 0 | AF8: 0 | AG8: 0 | AH8: 0 | AI8: 0 | AJ8: 27153.95 | AK8: 1
B9: Unit 5 EB Incomer | C9: 11KV Incomer Breaker06:00 to 10:00 | D9: 06:00 to 10:00 | E9: 66.438244 | F9: 11.5 | G9: 58.021875 | H9: 54.890625 | I9: 52.309375 | J9: 51.429726 | K9: 57.46165 | L9: 51.573438 | M9: 9.6875 | N9: 44.096875 | O9: 48.695884 | P9: 46.190625 | Q9: 58.690625 | R9: 45.292187 | S9: 12.35061 | T9: 28.350818 | U9: 58.067428 | V9: 0 | W9: 0 | X9: 0 | Y9: 0 | Z9: 0 | AA9: 0 | AB9: 0 | AC9: 0 | AD9: 0 | AE9: 0 | AF9: 0 | AG9: 0 | AH9: 0 | AI9: 0 | AJ9: 755.04748 | AK9: 0.12871083
C10: 11KV Incomer Breaker10:00 to 18:00 | D10: 10:00 to 18:00 | E10: 84.739881 | F10: 26.142188 | G10: 88.29399 | H10: 100.925 | I10: 91.0375 | J10: 92.084375 | K10: 90.810061 | L10: 79.076562 | M10: 24.887195 | N10: 104.44087 | O10: 102.53506 | P10: 93.309375 | Q10: 81.671875 | R10: 117.16094 | S10: 27.623476 | T10: 26.382812 | U10: 143.45132 | V10: 0 | W10: 0 | X10: 0 | Y10: 0 | Z10: 0 | AA10: 0 | AB10: 0 | AC10: 0 | AD10: 0 | AE10: 0 | AF10: 0 | AG10: 0 | AH10: 0 | AI10: 0 | AJ10: 1374.5725 | AK10: 0.23431952
C11: 11KV Incomer Breaker18:00 to 22:00 | D11: 18:00 to 22:00 | E11: 96.2375 | F11: 20.033117 | G11: 93.271635 | H11: 73.298077 | I11: 83.252591 | J11: 80.235938 | K11: 79.554268 | L11: 89.132812 | M11: 19.789367 | N11: 84.997352 | O11: 77.750305 | P11: 87.73125 | Q11: 0 | R11: 80.448438 | S11: 20.440625 | T11: 55.324695 | U11: 122.68281 | V11: 0 | W11: 0 | X11: 0 | Y11: 0 | Z11: 0 | AA11: 0 | AB11: 0 | AC11: 0 | AD11: 0 | AE11: 0 | AF11: 0 | AG11: 0 | AH11: 0 | AI11: 0 | AJ11: 1164.1808 | AK11: 0.19845464
C12: 11KV Incomer Breaker22:00 to 06:00 | D12: 22:00 to 06:00 | E12: 176.1 | F12: 41.330945 | G12: 159.46562 | H12: 185.2488 | I12: 160.16768 | J12: 163.18923 | K12: 168.88792 | L12: 163.1875 | M12: 37.196875 | N12: 188.93521 | O12: 197.2125 | P12: 243.18125 | Q12: 222.30469 | R12: 208.31966 | S12: 38.325744 | T12: 39.679992 | U12: 179.69687 | V12: 0 | W12: 0 | X12: 0 | Y12: 0 | Z12: 0 | AA12: 0 | AB12: 0 | AC12: 0 | AD12: 0 | AE12: 0 | AF12: 0 | AG12: 0 | AH12: 0 | AI12: 0 | AJ12: 2572.4305 | AK12: 0.43851502
D13: Total | E13: 423.51562 | F13: 99.00625 | G13: 399.05312 | H13: 414.3625 | I13: 386.76715 | J13: 386.93927 | K13: 396.7139 | L13: 382.97031 | M13: 91.560937 | N13: 422.47031 | O13: 426.19375 | P13: 470.4125 | Q13: 362.66719 | R13: 451.22123 | S13: 98.740454 | T13: 149.73832 | U13: 503.89844 | V13: 0 | W13: 0 | X13: 0 | Y13: 0 | Z13: 0 | AA13: 0 | AB13: 0 | AC13: 0 | AD13: 0 | AE13: 0 | AF13: 0 | AG13: 0 | AH13: 0 | AI13: 0 | AJ13: 5866.2312 | AK13: 1
B14: Unit 1 DG 1 - 365KVA | C14: 11KV ATS O/G Breaker06:00 to 10:00 | D14: 06:00 to 10:00 | E14: 0 | F14: 0 | G14: 0 | H14: 0 | I14: 0 | J14: 0 | K14: 0 | L14: 0 | M14: 0 | N14: 0 | O14: 0 | P14: 0 | Q14: 0 | R14: 0 | S14: 0 | T14: 0 | U14: 0 | V14: 0 | W14: 0 | X14: 0 | Y14: 0 | Z14: 0 | AA14: 0 | AB14: 0 | AC14: 0 | AD14: 0 | AE14: 0 | AF14: 0 | AG14: 0 | AH14: 0 | AI14: 0 | AJ14: 0 | AK14: 0
C15: 11KV ATS O/G Breaker10:00 to 18:00 | D15: 10:00 to 18:00 | E15: 0 | F15: 0 | G15: 0 | H15: 0 | I15: 0 | J15: 0 | K15: 0 | L15: 30.980469 | M15: 2.8984375 | N15: 0 | O15: 0 | P15: 519.09375 | Q15: 0 | R15: 0 | S15: 0 | T15: 0 | U15: 0 | V15: 0 | W15: 0 | X15: 0 | Y15: 0 | Z15: 0 | AA15: 0 | AB15: 0 | AC15: 0 | AD15: 0 | AE15: 0 | AF15: 0 | AG15: 0 | AH15: 0 | AI15: 0 | AJ15: 552.97266 | AK15: 0.65255331
C16: 11KV ATS O/G Breaker18:00 to 22:00 | D16: 18:00 to 22:00 | E16: 0 | F16: 81.300391 | G16: 0 | H16: 0 | I16: 36 | J16: 0 | K16: 0 | L16: 50.847656 | M16: 0 | N16: 0 | O16: 0 | P16: 0 | Q16: 0 | R16: 0 | S16: 0 | T16: 0 | U16: 0 | V16: 0 | W16: 0 | X16: 0 | Y16: 0 | Z16: 0 | AA16: 0 | AB16: 0 | AC16: 0 | AD16: 0 | AE16: 0 | AF16: 0 | AG16: 0 | AH16: 0 | AI16: 0 | AJ16: 168.14805 | AK16: 0.19842855
C17: 11KV ATS O/G Breaker22:00 to 06:00 | D17: 22:00 to 06:00 | E17: 0 | F17: 126.27773 | G17: 0 | H17: 0 | I17: 0 | J17: 0 | K17: 0 | L17: 0 | M17: 0 | N17: 0 | O17: 0 | P17: 0 | Q17: 0 | R17: 0 | S17: 0 | T17: 0 | U17: 0 | V17: 0 | W17: 0 | X17: 0 | Y17: 0 | Z17: 0 | AA17: 0 | AB17: 0 | AC17: 0 | AD17: 0 | AE17: 0 | AF17: 0 | AG17: 0 | AH17: 0 | AI17: 0 | AJ17: 126.27773 | AK17: 0.14901813
D18: Total | E18: 0 | F18: 207.57812 | G18: 0 | H18: 0 | I18: 36 | J18: 0 | K18: 0 | L18: 81.828125 | M18: 2.8984375 | N18: 0 | O18: 0 | P18: 519.09375 | Q18: 0 | R18: 0 | S18: 0 | T18: 0 | U18: 0 | V18: 0 | W18: 0 | X18: 0 | Y18: 0 | Z18: 0 | AA18: 0 | AB18: 0 | AC18: 0 | AD18: 0 | AE18: 0 | AF18: 0 | AG18: 0 | AH18: 0 | AI18: 0 | AJ18: 847.39844 | AK18: 1
B19: Unit 1 DG 2 - 380KVA | C19: 11KV Module & Cell O/G Breaker06:00 to 10:00 | D19: 06:00 to 10:00 | E19: 0 | F19: 0 | G19: 0 | H19: 0 | I19: 0 | J19: 0 | K19: 0 | L19: 0 | M19: 0 | N19: 0 | O19: 0 | P19: 0 | Q19: 0 | R19: 0 | S19: 0 | T19: 0 | U19: 0 | V19: 0 | W19: 0 | X19: 0 | Y19: 0 | Z19: 0 | AA19: 0 | AB19: 0 | AC19: 0 | AD19: 0 | AE19: 0 | AF19: 0 | AG19: 0 | AH19: 0 | AI19: 0 | AJ19: 0 | AK19: -
C20: 11KV Module & Cell O/G Breaker10:00 to 18:00 | D20: 10:00 to 18:00 | E20: 0 | F20: 0 | G20: 0 | H20: 0 | I20: 0 | J20: 0 | K20: 0 | L20: 0 | M20: 0 | N20: 0 | O20: 0 | P20: 0 | Q20: 0 | R20: 0 | S20: 0 | T20: 0 | U20: 0 | V20: 0 | W20: 0 | X20: 0 | Y20: 0 | Z20: 0 | AA20: 0 | AB20: 0 | AC20: 0 | AD20: 0 | AE20: 0 | AF20: 0 | AG20: 0 | AH20: 0 | AI20: 0 | AJ20: 0 | AK20: -
C21: 11KV Module & Cell O/G Breaker18:00 to 22:00 | D21: 18:00 to 22:00 | E21: 0 | F21: 0 | G21: 0 | H21: 0 | I21: 0 | J21: 0 | K21: 0 | L21: 0 | M21: 0 | N21: 0 | O21: 0 | P21: 0 | Q21: 0 | R21: 0 | S21: 0 | T21: 0 | U21: 0 | V21: 0 | W21: 0 | X21: 0 | Y21: 0 | Z21: 0 | AA21: 0 | AB21: 0 | AC21: 0 | AD21: 0 | AE21: 0 | AF21: 0 | AG21: 0 | AH21: 0 | AI21: 0 | AJ21: 0 | AK21: -
C22: 11KV Module & Cell O/G Breaker22:00 to 06:00 | D22: 22:00 to 06:00 | E22: 0 | F22: 0 | G22: 0 | H22: 0 | I22: 0 | J22: 0 | K22: 0 | L22: 0 | M22: 0 | N22: 0 | O22: 0 | P22: 0 | Q22: 0 | R22: 0 | S22: 0 | T22: 0 | U22: 0 | V22: 0 | W22: 0 | X22: 0 | Y22: 0 | Z22: 0 | AA22: 0 | AB22: 0 | AC22: 0 | AD22: 0 | AE22: 0 | AF22: 0 | AG22: 0 | AH22: 0 | AI22: 0 | AJ22: 0 | AK22: -
D23: Total | E23: 0 | F23: 0 | G23: 0 | H23: 0 | I23: 0 | J23: 0 | K23: 0 | L23: 0 | M23: 0 | N23: 0 | O23: 0 | P23: 0 | Q23: 0 | R23: 0 | S23: 0 | T23: 0 | U23: 0 | V23: 0 | W23: 0 | X23: 0 | Y23: 0 | Z23: 0 | AA23: 0 | AB23: 0 | AC23: 0 | AD23: 0 | AE23: 0 | AF23: 0 | AG23: 0 | AH23: 0 | AI23: 0 | AJ23: 0 | AK23: -
B24: Unit 5 DG Incomer | C24: Transformer - 1. O/G Breaker06:00 to 10:00 | D24: 06:00 to 10:00 | E24: 0 | F24: 0 | G24: 0 | H24: 0 | I24: 0 | J24: 0 | K24: 0 | L24: 0 | M24: 0 | N24: 0 | O24: 0 | P24: 0 | Q24: 0 | R24: 0 | S24: 0 | T24: 0 | U24: 0 | V24: 0 | W24: 0 | X24: 0 | Y24: 0 | Z24: 0 | AA24: 0 | AB24: 0 | AC24: 0 | AD24: 0 | AE24: 0 | AF24: 0 | AG24: 0 | AH24: 0 | AI24: 0 | AJ24: 0 | AK24: -
C25: Transformer - 1. O/G Breaker10:00 to 18:00 | D25: 10:00 to 18:00 | E25: 0 | F25: 0 | G25: 0 | H25: 0 | I25: 0 | J25: 0 | K25: 0 | L25: 0 | M25: 0 | N25: 0 | O25: 0 | P25: 0 | Q25: 0 | R25: 0 | S25: 0 | T25: 0 | U25: 0 | V25: 0 | W25: 0 | X25: 0 | Y25: 0 | Z25: 0 | AA25: 0 | AB25: 0 | AC25: 0 | AD25: 0 | AE25: 0 | AF25: 0 | AG25: 0 | AH25: 0 | AI25: 0 | AJ25: 0 | AK25: -
C26: Transformer - 1. O/G Breaker18:00 to 22:00 | D26: 18:00 to 22:00 | E26: 0 | F26: 0 | G26: 0 | H26: 0 | I26: 0 | J26: 0 | K26: 0 | L26: 0 | M26: 0 | N26: 0 | O26: 0 | P26: 0 | Q26: 0 | R26: 0 | S26: 0 | T26: 0 | U26: 0 | V26: 0 | W26: 0 | X26: 0 | Y26: 0 | Z26: 0 | AA26: 0 | AB26: 0 | AC26: 0 | AD26: 0 | AE26: 0 | AF26: 0 | AG26: 0 | AH26: 0 | AI26: 0 | AJ26: 0 | AK26: -
C27: Transformer - 1. O/G Breaker22:00 to 06:00 | D27: 22:00 to 06:00 | E27: 0 | F27: 0 | G27: 0 | H27: 0 | I27: 0 | J27: 0 | K27: 0 | L27: 0 | M27: 0 | N27: 0 | O27: 0 | P27: 0 | Q27: 0 | R27: 0 | S27: 0 | T27: 0 | U27: 0 | V27: 0 | W27: 0 | X27: 0 | Y27: 0 | Z27: 0 | AA27: 0 | AB27: 0 | AC27: 0 | AD27: 0 | AE27: 0 | AF27: 0 | AG27: 0 | AH27: 0 | AI27: 0 | AJ27: 0 | AK27: -
D28: Total | E28: 0 | F28: 0 | G28: 0 | H28: 0 | I28: 0 | J28: 0 | K28: 0 | L28: 0 | M28: 0 | N28: 0 | O28: 0 | P28: 0 | Q28: 0 | R28: 0 | S28: 0 | T28: 0 | U28: 0 | V28: 0 | W28: 0 | X28: 0 | Y28: 0 | Z28: 0 | AA28: 0 | AB28: 0 | AC28: 0 | AD28: 0 | AE28: 0 | AF28: 0 | AG28: 0 | AH28: 0 | AI28: 0 | AJ28: 0 | AK28: -

Sheet Formulas_Departments Summary
B3: Sr. No. | C3: Department | E3: =meta_sheet!A3 -> 46235 | F3: =E3+1 -> 46236 | G3: =F3+1 -> 46237 | H3: =G3+1 -> 46238 | I3: =H3+1 -> 46239 | J3: =I3+1 -> 46240 | K3: =J3+1 -> 46241 | L3: =K3+1 -> 46242 | M3: =L3+1 -> 46243 | ... AI3: =AH3+1 -> 46265
B4: EB | C4: Unit 1 EB Incomer | D4: 12819 | E4: =IFERROR(HLOOKUP($D4,'Monthly report'!$B$6:$F$37,COLUMN(B2),0),"-") -> 1522.6203 | F4: =IFERROR(HLOOKUP($D4,'Monthly report'!$B$6:$F$37,COLUMN(C2),0),"-") -> 868.43755 | G4: =IFERROR(HLOOKUP($D4,'Monthly report'!$B$6:$F$37,COLUMN(D2),0),"-") -> 1891.6047 | H4: =IFERROR(HLOOKUP($D4,'Monthly report'!$B$6:$F$37,COLUMN(E2),0),"-") -> 1908.8125 | I4: =IFERROR(HLOOKUP($D4,'Monthly report'!$B$6:$F$37,COLUMN(F2),0),"-") -> 1813.5 | J4: =IFERROR(HLOOKUP($D4,'Monthly report'!$B$6:$F$37,COLUMN(G2),0),"-") -> 1902.2792 | K4: =IFERROR(HLOOKUP($D4,'Monthly report'!$B$6:$F$37,COLUMN(H2),0),"-") -> 1833.4083 | L4: =IFERROR(HLOOKUP($D4,'Monthly report'!$B$6:$F$37,COLUMN(I2),0),"-") -> 1103.475 | ... AI4: =IFERROR(HLOOKUP($D4,'Monthly report'!$B$6:$F$37,COLUMN(AF2),0),"-") -> 0
C5: Unit 5 EB Incomer | D5: 13578 | E5: =IFERROR(HLOOKUP($D5,'Monthly report'!$B$6:$F$37,COLUMN(B3),0),"-") -> 423.51562 | F5: =IFERROR(HLOOKUP($D5,'Monthly report'!$B$6:$F$37,COLUMN(C3),0),"-") -> 99.00625 | G5: =IFERROR(HLOOKUP($D5,'Monthly report'!$B$6:$F$37,COLUMN(D3),0),"-") -> 399.05312 | H5: =IFERROR(HLOOKUP($D5,'Monthly report'!$B$6:$F$37,COLUMN(E3),0),"-") -> 414.3625 | I5: =IFERROR(HLOOKUP($D5,'Monthly report'!$B$6:$F$37,COLUMN(F3),0),"-") -> 386.76715 | J5: =IFERROR(HLOOKUP($D5,'Monthly report'!$B$6:$F$37,COLUMN(G3),0),"-") -> 386.93927 | K5: =IFERROR(HLOOKUP($D5,'Monthly report'!$B$6:$F$37,COLUMN(H3),0),"-") -> 396.7139 | L5: =IFERROR(HLOOKUP($D5,'Monthly report'!$B$6:$F$37,COLUMN(I3),0),"-") -> 382.97031 | ... AI5: =IFERROR(HLOOKUP($D5,'Monthly report'!$B$6:$F$37,COLUMN(AF3),0),"-") -> 0
B6: DG | C6: Unit 1 DG 1 - 365KVA | D6: 12817 | E6: =IFERROR(HLOOKUP($D6,'Monthly report'!$B$6:$F$37,COLUMN(B4),0),"-") -> 0 | F6: =IFERROR(HLOOKUP($D6,'Monthly report'!$B$6:$F$37,COLUMN(C4),0),"-") -> 207.57812 | G6: =IFERROR(HLOOKUP($D6,'Monthly report'!$B$6:$F$37,COLUMN(D4),0),"-") -> 0 | H6: =IFERROR(HLOOKUP($D6,'Monthly report'!$B$6:$F$37,COLUMN(E4),0),"-") -> 0 | I6: =IFERROR(HLOOKUP($D6,'Monthly report'!$B$6:$F$37,COLUMN(F4),0),"-") -> 36 | J6: =IFERROR(HLOOKUP($D6,'Monthly report'!$B$6:$F$37,COLUMN(G4),0),"-") -> 0 | K6: =IFERROR(HLOOKUP($D6,'Monthly report'!$B$6:$F$37,COLUMN(H4),0),"-") -> 0 | L6: =IFERROR(HLOOKUP($D6,'Monthly report'!$B$6:$F$37,COLUMN(I4),0),"-") -> 81.828125 | ... AI6: =IFERROR(HLOOKUP($D6,'Monthly report'!$B$6:$F$37,COLUMN(AF4),0),"-") -> 0
C7: Unit 1 DG 2 - 380KVA | D7: 12818 | E7: =IFERROR(HLOOKUP($D7,'Monthly report'!$B$6:$F$37,COLUMN(B5),0),"-") -> 0 | F7: =IFERROR(HLOOKUP($D7,'Monthly report'!$B$6:$F$37,COLUMN(C5),0),"-") -> 0 | G7: =IFERROR(HLOOKUP($D7,'Monthly report'!$B$6:$F$37,COLUMN(D5),0),"-") -> 0 | H7: =IFERROR(HLOOKUP($D7,'Monthly report'!$B$6:$F$37,COLUMN(E5),0),"-") -> 0 | I7: =IFERROR(HLOOKUP($D7,'Monthly report'!$B$6:$F$37,COLUMN(F5),0),"-") -> 0 | J7: =IFERROR(HLOOKUP($D7,'Monthly report'!$B$6:$F$37,COLUMN(G5),0),"-") -> 0 | K7: =IFERROR(HLOOKUP($D7,'Monthly report'!$B$6:$F$37,COLUMN(H5),0),"-") -> 0 | L7: =IFERROR(HLOOKUP($D7,'Monthly report'!$B$6:$F$37,COLUMN(I5),0),"-") -> 0 | ... AI7: =IFERROR(HLOOKUP($D7,'Monthly report'!$B$6:$F$37,COLUMN(AF5),0),"-") -> 0
C8: Unit 5 DG Incomer | D8: 13579 | E8: =IFERROR(HLOOKUP($D8,'Monthly report'!$B$6:$F$37,COLUMN(B6),0),"-") -> 0 | F8: =IFERROR(HLOOKUP($D8,'Monthly report'!$B$6:$F$37,COLUMN(C6),0),"-") -> 0.3515625 | G8: =IFERROR(HLOOKUP($D8,'Monthly report'!$B$6:$F$37,COLUMN(D6),0),"-") -> 0 | H8: =IFERROR(HLOOKUP($D8,'Monthly report'!$B$6:$F$37,COLUMN(E6),0),"-") -> 0 | I8: =IFERROR(HLOOKUP($D8,'Monthly report'!$B$6:$F$37,COLUMN(F6),0),"-") -> 0 | J8: =IFERROR(HLOOKUP($D8,'Monthly report'!$B$6:$F$37,COLUMN(G6),0),"-") -> 0 | K8: =IFERROR(HLOOKUP($D8,'Monthly report'!$B$6:$F$37,COLUMN(H6),0),"-") -> 0 | L8: =IFERROR(HLOOKUP($D8,'Monthly report'!$B$6:$F$37,COLUMN(I6),0),"-") -> 1.7695312 | ... AI8: =IFERROR(HLOOKUP($D8,'Monthly report'!$B$6:$F$37,COLUMN(AF6),0),"-") -> 0

Sheet Formulas_Graphs
C1: Select Location | E1: Unit 1 DG 1 - 365KVA | H1: =VLOOKUP(E1,Z:AA,2,0) -> 12817
Z7: Unit 1 EB Incomer | AA7: 12819
Z8: Unit 1 DG 1 - 365KVA | AA8: 12817
Z9: Unit 1 DG 2 - 380KVA | AA9: 12818
Z10: Unit 5 DG Incomer | AA10: 13579
Z11: Unit 5 EB Incomer | AA11: 13578
C26: 06:00 to 10:00 | D26: 10:00 to 18:00 | E26: 18:00 to 22:00 | F26: 22:00 to 06:00
B27: Date | C27: Morning Time | D27: Normal Time | E27: Evening Time | F27: NIght
B28: =' Formulas_TODwise Consumption R'!E3 -> 46235 | C28: =HLOOKUP($H$1,TOD!$C$5:$G$36,ROW(A2),0) -> 0 | D28: =HLOOKUP($H$1,TOD!$C$38:$G$70,ROW(A3),0) -> 0 | E28: =HLOOKUP($H$1,TOD!$C$73:$G$105,ROW(A3),0) -> 0 | F28: =HLOOKUP($H$1,TOD!$C$107:$G$139,ROW(A3),0) -> 0
B29: =B28+1 -> 46236 | C29: =HLOOKUP($H$1,TOD!$C$5:$G$36,ROW(A3),0) -> 0 | D29: =HLOOKUP($H$1,TOD!$C$38:$G$70,ROW(A4),0) -> 0 | E29: =HLOOKUP($H$1,TOD!$C$73:$G$105,ROW(A4),0) -> 81.300391 | F29: =HLOOKUP($H$1,TOD!$C$107:$G$139,ROW(A4),0) -> 126.27773
B30: =B29+1 -> 46237 | C30: =HLOOKUP($H$1,TOD!$C$5:$G$36,ROW(A4),0) -> 0 | D30: =HLOOKUP($H$1,TOD!$C$38:$G$70,ROW(A5),0) -> 0 | E30: =HLOOKUP($H$1,TOD!$C$73:$G$105,ROW(A5),0) -> 0 | F30: =HLOOKUP($H$1,TOD!$C$107:$G$139,ROW(A5),0) -> 0
B31: =B30+1 -> 46238 | C31: =HLOOKUP($H$1,TOD!$C$5:$G$36,ROW(A5),0) -> 0 | D31: =HLOOKUP($H$1,TOD!$C$38:$G$70,ROW(A6),0) -> 0 | E31: =HLOOKUP($H$1,TOD!$C$73:$G$105,ROW(A6),0) -> 0 | F31: =HLOOKUP($H$1,TOD!$C$107:$G$139,ROW(A6),0) -> 0
B32: =B31+1 -> 46239 | C32: =HLOOKUP($H$1,TOD!$C$5:$G$36,ROW(A6),0) -> 0 | D32: =HLOOKUP($H$1,TOD!$C$38:$G$70,ROW(A7),0) -> 0 | E32: =HLOOKUP($H$1,TOD!$C$73:$G$105,ROW(A7),0) -> 36 | F32: =HLOOKUP($H$1,TOD!$C$107:$G$139,ROW(A7),0) -> 0
B33: =B32+1 -> 46240 | C33: =HLOOKUP($H$1,TOD!$C$5:$G$36,ROW(A7),0) -> 0 | D33: =HLOOKUP($H$1,TOD!$C$38:$G$70,ROW(A8),0) -> 0 | E33: =HLOOKUP($H$1,TOD!$C$73:$G$105,ROW(A8),0) -> 0 | F33: =HLOOKUP($H$1,TOD!$C$107:$G$139,ROW(A8),0) -> 0
B34: =B33+1 -> 46241 | C34: =HLOOKUP($H$1,TOD!$C$5:$G$36,ROW(A8),0) -> 0 | D34: =HLOOKUP($H$1,TOD!$C$38:$G$70,ROW(A9),0) -> 0 | E34: =HLOOKUP($H$1,TOD!$C$73:$G$105,ROW(A9),0) -> 0 | F34: =HLOOKUP($H$1,TOD!$C$107:$G$139,ROW(A9),0) -> 0
B35: =B34+1 -> 46242 | C35: =HLOOKUP($H$1,TOD!$C$5:$G$36,ROW(A9),0) -> 0 | D35: =HLOOKUP($H$1,TOD!$C$38:$G$70,ROW(A10),0) -> 30.980469 | E35: =HLOOKUP($H$1,TOD!$C$73:$G$105,ROW(A10),0) -> 50.847656 | F35: =HLOOKUP($H$1,TOD!$C$107:$G$139,ROW(A10),0) -> 0
B36: =B35+1 -> 46243 | C36: =HLOOKUP($H$1,TOD!$C$5:$G$36,ROW(A10),0) -> 0 | D36: =HLOOKUP($H$1,TOD!$C$38:$G$70,ROW(A11),0) -> 2.8984375 | E36: =HLOOKUP($H$1,TOD!$C$73:$G$105,ROW(A11),0) -> 0 | F36: =HLOOKUP($H$1,TOD!$C$107:$G$139,ROW(A11),0) -> 0
B37: =B36+1 -> 46244 | C37: =HLOOKUP($H$1,TOD!$C$5:$G$36,ROW(A11),0) -> 0 | D37: =HLOOKUP($H$1,TOD!$C$38:$G$70,ROW(A12),0) -> 0 | E37: =HLOOKUP($H$1,TOD!$C$73:$G$105,ROW(A12),0) -> 0 | F37: =HLOOKUP($H$1,TOD!$C$107:$G$139,ROW(A12),0) -> 0
B38: =B37+1 -> 46245 | C38: =HLOOKUP($H$1,TOD!$C$5:$G$36,ROW(A12),0) -> 0 | D38: =HLOOKUP($H$1,TOD!$C$38:$G$70,ROW(A13),0) -> 0 | E38: =HLOOKUP($H$1,TOD!$C$73:$G$105,ROW(A13),0) -> 0 | F38: =HLOOKUP($H$1,TOD!$C$107:$G$139,ROW(A13),0) -> 0
B39: =B38+1 -> 46246 | C39: =HLOOKUP($H$1,TOD!$C$5:$G$36,ROW(A13),0) -> 0 | D39: =HLOOKUP($H$1,TOD!$C$38:$G$70,ROW(A14),0) -> 519.09375 | E39: =HLOOKUP($H$1,TOD!$C$73:$G$105,ROW(A14),0) -> 0 | F39: =HLOOKUP($H$1,TOD!$C$107:$G$139,ROW(A14),0) -> 0
B40: =B39+1 -> 46247 | C40: =HLOOKUP($H$1,TOD!$C$5:$G$36,ROW(A14),0) -> 0 | D40: =HLOOKUP($H$1,TOD!$C$38:$G$70,ROW(A15),0) -> 0 | E40: =HLOOKUP($H$1,TOD!$C$73:$G$105,ROW(A15),0) -> 0 | F40: =HLOOKUP($H$1,TOD!$C$107:$G$139,ROW(A15),0) -> 0
... B58: =B57+1 -> 46265 | C58: =HLOOKUP($H$1,TOD!$C$5:$G$36,ROW(A32),0) -> 0 | D58: =HLOOKUP($H$1,TOD!$C$38:$G$70,ROW(A33),0) -> 0 | E58: =HLOOKUP($H$1,TOD!$C$73:$G$105,ROW(A33),0) -> 0 | F58: =HLOOKUP($H$1,TOD!$C$107:$G$139,ROW(A33),0) -> 0

Sheet Monthly report
A1: Progressive Report | N1: 46251 | O1: UNIT 1 | R1: UNIT 2
O2: Unit 1 EB Incomer | P2: Unit 1 DG 1 - 365KVA | Q2: Unit 1 DG 2 - 380KVA | R2: Unit 5 DG Incomer | S2: Unit 5 EB Incomer | T2: Unit 5 AC Store Room - Temperature | U2: Unit 5 AC Store Room - Humidity
B3: UNIT 1 | E3: UNIT 2 | O3: kwh | T3: Temperature | U3: Humidity
A4: Date | B4: Unit 1 EB Incomer | C4: Unit 1 DG 1 - 365KVA | D4: Unit 1 DG 2 - 380KVA | E4: Unit 5 DG Incomer | F4: Unit 5 EB Incomer | O4: 12819 | P4: 12817 | Q4: 12818 | R4: 13579 | S4: 13578 | T4: 14205 | U4: 14204
B5: kwh | O5: 1870.3953 | P5: 0 | Q5: 0 | R5: 0 | S5: 503.89844
B6: 12819 | C6: 12817 | D6: 12818 | E6: 13579 | F6: 13578
A7: 46235 | B7: 1522.6203 | C7: 0 | D7: 0 | E7: 0 | F7: 423.51562
A8: 46236 | B8: 868.43755 | C8: 207.57812 | D8: 0 | E8: 0.3515625 | F8: 99.00625
A9: 46237 | B9: 1891.6047 | C9: 0 | D9: 0 | E9: 0 | F9: 399.05312
A10: 46238 | B10: 1908.8125 | C10: 0 | D10: 0 | E10: 0 | F10: 414.3625
A11: 46239 | B11: 1813.5 | C11: 36 | D11: 0 | E11: 0 | F11: 386.76715
A12: 46240 | B12: 1902.2792 | C12: 0 | D12: 0 | E12: 0 | F12: 386.93927
A13: 46241 | B13: 1833.4083 | C13: 0 | D13: 0 | E13: 0 | F13: 396.7139
A14: 46242 | B14: 1103.475 | C14: 81.828125 | D14: 0 | E14: 1.7695312 | F14: 382.97031
A15: 46243 | B15: 965.01148 | C15: 2.8984375 | D15: 0 | E15: 0 | F15: 91.560937
A16: 46244 | B16: 1922.476 | C16: 0 | D16: 0 | E16: 0 | F16: 422.47031
A17: 46245 | B17: 2046.825 | C17: 0 | D17: 0 | E17: 0 | F17: 426.19375
A18: 46246 | B18: 1530.7292 | C18: 519.09375 | D18: 0 | E18: 0.51171875 | F18: 470.4125
... A23: 46251 | B23: 1870.3953 | C23: 0 | D23: 0 | E23: 0 | F23: 503.89844
A24: 46252
A25: 46253
A26: 46254
A27: 46255
A28: 46256
A29: 46257
A30: 46258
A31: 46259
A32: 46260
A33: 46261
A34: 46262
A35: 46263
... A37: 46265
A39: Total | B39: 27153.95 | C39: 847.39844 | D39: 0 | E39: 161.58398 | F39: 5866.2312

Sheet Sheet9
C1: kwh | J1: 480
D2: Unit 1 EB Incomer | E2: Unit 1 DG 1 - 365KVA | F2: Unit 1 DG 2 - 380KVA | G2: Unit 5 DG Incomer | H2: Unit 5 EB Incomer
D3: 12819 | E3: 12817 | F3: 12818 | G3: 13579 | H3: 13578
C4: 46235.25 | D4: 591.67083 | E4: 0 | F4: 0 | G4: 0 | H4: 106.83437
C5: 46235.583 | D5: 595.91667 | E5: 0 | F5: 0 | G5: 0 | H5: 140.58125
C6: 46235.917 | D6: 335.03279 | E6: 0 | F6: 0 | G6: 0 | H6: 176.1
C7: 46236.25 | D7: 329.53279 | E7: 0 | F7: 0 | G7: 0.3515625 | H7: 23.409375
C8: 46236.583 | D8: 323.5306 | E8: 81.300391 | F8: 0 | G8: 0 | H8: 34.26593
C9: 46236.917 | D9: 215.37416 | E9: 126.27773 | F9: 0 | G9: 0 | H9: 41.330945
C10: 46237.25 | D10: 821.74687 | E10: 0 | F10: 0 | G10: 0 | H10: 96.520312
C11: 46237.583 | D11: 707.33279 | E11: 0 | F11: 0 | G11: 0 | H11: 143.06719
C12: 46237.917 | D12: 362.525 | E12: 0 | F12: 0 | G12: 0 | H12: 159.46562
C13: 46238.25 | D13: 839.79167 | E13: 0 | F13: 0 | G13: 0 | H13: 108.33281
C14: 46238.583 | D14: 725.50833 | E14: 0 | F14: 0 | G14: 0 | H14: 120.78089
C15: 46238.917 | D15: 343.5125 | E15: 0 | F15: 0 | G15: 0 | H15: 185.2488
... C54: 46251.917 | D54: 335.2875 | E54: 0 | F54: 0 | G54: 0 | H54: 179.69687

Sheet meta_sheet
A1: 0.25
A2: 1440
A3: 46235
A4: 46252
A10: 1457

Sheet TOD
C1: Unit 1 EB Incomer | D1: Unit 5 EB Incomer | E1: Unit 1 DG 1 - 365KVA | F1: Unit 1 DG 2 - 380KVA | G1: Unit 5 DG Incomer
C2: 12819 | D2: 13578 | E2: 12817 | F2: 12818 | G2: 13579
B3: Peak (morning) | C3: Unit 1 EB Incomer | D3: Unit 5 EB Incomer | E3: Unit 1 DG 1 - 365KVA | F3: Unit 1 DG 2 - 380KVA | G3: Unit 5 DG Incomer
C4: 06:00 to 10:00 | D4: 06:00 to 10:00 | E4: 06:00 to 10:00 | F4: 06:00 to 10:00 | G4: 06:00 to 10:00
C5: 12819 | D5: 13578 | E5: 12817 | F5: 12818 | G5: 13579
B6: 46235 | C6: 250.275 | D6: 66.438244 | E6: 0 | F6: 0 | G6: 0
B7: 46236 | C7: 165.48416 | D7: 11.5 | E7: 0 | F7: 0 | G7: 0
B8: 46237 | C8: 360.76242 | D8: 58.021875 | E8: 0 | F8: 0 | G8: 0
B9: 46238 | C9: 373.74167 | D9: 54.890625 | E9: 0 | F9: 0 | G9: 0
B10: 46239 | C10: 361.775 | D10: 52.309375 | E10: 0 | F10: 0 | G10: 0
B11: 46240 | C11: 342.67917 | D11: 51.429726 | E11: 0 | F11: 0 | G11: 0
B12: 46241 | C12: 368 | D12: 57.46165 | E12: 0 | F12: 0 | G12: 0
B13: 46242 | C13: 240.94549 | D13: 51.573438 | E13: 0 | F13: 0 | G13: 0
B14: 46243 | C14: 154.31667 | D14: 9.6875 | E14: 0 | F14: 0 | G14: 0
B15: 46244 | C15: 343.08852 | D15: 44.096875 | E15: 0 | F15: 0 | G15: 0
B16: 46245 | C16: 363.04857 | D16: 48.695884 | E16: 0 | F16: 0 | G16: 0
B17: 46246 | C17: 368.1875 | D17: 46.190625 | E17: 0 | F17: 0 | G17: 0
... B36: 46265 | C36: 0 | D36: 0 | E36: 0 | F36: 0 | G36: 0
B38: Normal time | C38: 12819 | D38: 13578 | E38: 12817 | F38: 12818 | G38: 13579
C39: Unit 1 EB Incomer | D39: Unit 5 EB Incomer | E39: Unit 1 DG 1 - 365KVA | F39: Unit 1 DG 2 - 380KVA | G39: Unit 5 DG Incomer
B40: 46235 | C40: 719.49693 | D40: 84.739881 | E40: 0 | F40: 0 | G40: 0
B41: 46236 | C41: 362.30272 | D41: 26.142188 | E41: 0 | F41: 0 | G41: 0.3515625
B42: 46237 | C42: 888.82759 | D42: 88.29399 | E42: 0 | F42: 0 | G42: 0
B43: 46238 | C43: 916.78333 | D43: 100.925 | E43: 0 | F43: 0 | G43: 0
B44: 46239 | C44: 889.7625 | D44: 91.0375 | E44: 0 | F44: 0 | G44: 0
B45: 46240 | C45: 880.53333 | D45: 92.084375 | E45: 0 | F45: 0 | G45: 0
B46: 46241 | C46: 861.125 | D46: 90.810061 | E46: 0 | F46: 0 | G46: 0
B47: 46242 | C47: 416.60637 | D47: 79.076562 | E47: 30.980469 | F47: 0 | G47: 1.7695312
B48: 46243 | C48: 305.19583 | D48: 24.887195 | E48: 2.8984375 | F48: 0 | G48: 0
B49: 46244 | C49: 936.4 | D49: 104.44087 | E49: 0 | F49: 0 | G49: 0
B50: 46245 | C50: 1010.0598 | D50: 102.53506 | E50: 0 | F50: 0 | G50: 0
B51: 46246 | C51: 491.03333 | D51: 93.309375 | E51: 519.09375 | F51: 0 | G51: 0.51171875
... B70: 46265 | C70: 0 | D70: 0 | E70: 0 | F70: 0 | G70: 0
B73: Peak (Evening) | C73: 12819 | D73: 13578 | E73: 12817 | F73: 12818 | G73: 13579
C74: Unit 1 EB Incomer | D74: Unit 5 EB Incomer | E74: Unit 1 DG 1 - 365KVA | F74: Unit 1 DG 2 - 380KVA | G74: Unit 5 DG Incomer
B75: 46235 | C75: 217.81557 | D75: 96.2375 | E75: 0 | F75: 0 | G75: 0
B76: 46236 | C76: 125.2765 | D76: 20.033117 | E76: 81.300391 | F76: 0 | G76: 0
B77: 46237 | C77: 279.48966 | D77: 93.271635 | E77: 0 | F77: 0 | G77: 0
B78: 46238 | C78: 274.775 | D78: 73.298077 | E78: 0 | F78: 0 | G78: 0
B79: 46239 | C79: 223.9625 | D79: 83.252591 | E79: 36 | F79: 0 | G79: 0
...

Sheet shiftdata 24hours
A1: KWH | C1: 60
E3: 12819 | F3: 13578 | G3: 12817 | H3: 12818 | I3: 13579
E4: 6 TO 10
E5: Unit 1 EB Incomer | F5: Unit 5 EB Incomer | G5: Unit 1 DG 1 - 365KVA | H5: Unit 1 DG 2 - 380KVA | I5: Unit 5 DG Incomer
A6: 462350.25 | B6: 46235 | C6: 0.25 | D6: 0.29166667 | E6: 52.6375 | F6: 15.896723 | G6: 0 | H6: 0 | I6: 0
A7: 462350.291666666666667 | B7: 46235 | C7: 0.29166667 | D7: 0.33333333 | E7: 64.666667 | F7: 27.887652 | G7: 0 | H7: 0 | I7: 0
A8: 462350.333333333333333 | B8: 46235 | C8: 0.33333333 | D8: 0.375 | E8: 68.410452 | F8: 11.201488 | G8: 0 | H8: 0 | I8: 0
A9: 462350.375 | B9: 46235 | C9: 0.375 | D9: 0.41666667 | E9: 64.560381 | F9: 11.452381 | G9: 0 | H9: 0 | I9: 0
A10: 462350.416666666666667 | B10: 46235 | C10: 0.41666667 | D10: 0.45833333 | E10: 66.645833 | F10: 8.2103938 | G10: 0 | H10: 0 | I10: 0
A11: 462350.458333333333333 | B11: 46235 | C11: 0.45833333 | D11: 0.5 | E11: 72.3 | F11: 9.9716747 | G11: 0 | H11: 0 | I11: 0
A12: 462350.5 | B12: 46235 | C12: 0.5 | D12: 0.54166667 | E12: 105.14167 | F12: 10.45 | G12: 0 | H12: 0 | I12: 0
A13: 462350.541666666666667 | B13: 46235 | C13: 0.54166667 | D13: 0.58333333 | E13: 97.308333 | F13: 11.764062 | G13: 0 | H13: 0 | I13: 0
A14: 462350.583333333333333 | B14: 46235 | C14: 0.58333333 | D14: 0.625 | E14: 103.21667 | F14: 10.44497 | G14: 0 | H14: 0 | I14: 0
A15: 462350.625 | B15: 46235 | C15: 0.625 | D15: 0.66666667 | E15: 99.033333 | F15: 7.5956555 | G15: 0 | H15: 0 | I15: 0
A16: 462350.666666666666667 | B16: 46235 | C16: 0.66666667 | D16: 0.70833333 | E16: 87.883333 | F16: 12.2375 | G16: 0 | H16: 0 | I16: 0
A17: 462350.708333333333333 | B17: 46235 | C17: 0.70833333 | D17: 0.75 | E17: 87.96776 | F17: 14.065625 | G17: 0 | H17: 0 | I17: 0
... A413: 462510.208333333333333 | B413: 46251 | C413: 0.20833333 | D413: 0.25 | E413: 40.4375 | F413: 27.921875 | G413: 0 | H413: 0 | I413: 0
A414: 462520.25 | B414: 46252 | C414: 0.25 | D414: 0.29166667
A415: 462520.291666666666667 | B415: 46252 | C415: 0.29166667 | D415: 0.33333333
A416: 462520.333333333333333 | B416: 46252 | C416: 0.33333333 | D416: 0.375
A417: 462520.375 | B417: 46252 | C417: 0.375 | D417: 0.41666667
A418: 462520.416666666666667 | B418: 46252 | C418: 0.41666667 | D418: 0.45833333
A419: 462520.458333333333333 | B419: 46252 | C419: 0.45833333 | D419: 0.5
A420: 462520.5 | B420: 46252 | C420: 0.5 | D420: 0.54166667
A421: 462520.541666666666667 | B421: 46252 | C421: 0.54166667 | D421: 0.58333333
A422: 462520.583333333333333 | B422: 46252 | C422: 0.58333333 | D422: 0.625
A423: 462520.625 | B423: 46252 | C423: 0.625 | D423: 0.66666667
A424: 462520.666666666666667 | B424: 46252 | C424: 0.66666667 | D424: 0.70833333
A425: 462520.708333333333333 | B425: 46252 | C425: 0.70833333 | D425: 0.75
... A773: 462660.208333333333333 | B773: 46266 | C773: 0.20833333 | D773: 0.25

Sheet Data
A1: 1016 | B1: Tata Power Solar Systems Ltd. | C1: 11902 | D1: MV - 2 UPS 3-400KVA Cell 2 | E1: M28 | F1: 8175657f#1 | G1: TRUE | H1: FALSE | I1: tata_Solar | J1: TPREL | K1: Bangalore | L1: mahadeva.prasad@tatapower.com | M1: 9900283898 | N1: kWh, kW, VOLTAGE (LN), CURRENT, FREQUENCY, Power Factor, KVAR, KVA, KVA (R PHASE), KVA (Y PHASE), KVA (B PHASE), VOLTAGE (LL), VOLTAGE (LL RY Phase), VOLTAGE (LL YB Phase), VOLTAGE (LL BR Phase), VOLTAGE (LN R Phase), VOLTAGE (LN Y PHASE), VOLTAGE (LN B PHASE), CURRENT (R PHASE), CURRENT (Y PHASE), CURRENT (B PHASE), KVAh, VOLTAGE THD (R PHASE), VOLTAGE THD (Y PHASE), VOLTAGE THD (B PHASE), CURRENT THD (R PHASE), CURRENT THD (Y PHASE), CURRENT THD (B PHASE), KVARh (INDUCTIVE RECEIVED), KVARh (CAPACITIVE RECEIVED), MAXIMUM DEMAND, KW (R PHASE), KW (Y PHASE), KW (B PHASE), KVAR (R PHASE), KVAR (Y PHASE), KVAR (B PHASE), KWh (DELIVERED), KVAh (DELIVERED), KVARh (INDUCTIVE DELIVERED), KVARh (CAPACITIVE DELIVERED), VOLTAGE THD, CURRENT THD, POWER FACTOR (R PHASE), POWER FACTOR (Y PHASE), POWER FACTOR (B PHASE), RISING DEMAND, PRESENT DEMAND, ON HOURS, INTERRUPTIONS, Total KWh data, Run Hours Import, Run Hours Export, RAW Power Factor, RAW POWER FACTOR (R PHASE), RAW POWER FACTOR (Y PHASE), RAW POWER FACTOR (B PHASE), Unit Operating Hours, Health Indicator, Scope 1 Emission
A2: 1016 | B2: Tata Power Solar Systems Ltd. | C2: 12181 | D2: MV-2 SMSB | E2: M652 | F2: 8175657f#4 | G2: FALSE | H2: FALSE | I2: tata_Solar | J2: TPREL | K2: Bangalore | L2: mahadeva.prasad@tatapower.com | M2: 9900283898 | N2: kWh, kW, VOLTAGE (LN), CURRENT, FREQUENCY, Power Factor, KVAR, KVA, KVA (R PHASE), KVA (Y PHASE), KVA (B PHASE), VOLTAGE (LL), VOLTAGE (LL RY Phase), VOLTAGE (LL YB Phase), VOLTAGE (LL BR Phase), VOLTAGE (LN R Phase), VOLTAGE (LN Y PHASE), VOLTAGE (LN B PHASE), CURRENT (R PHASE), CURRENT (Y PHASE), CURRENT (B PHASE), KVAh, VOLTAGE THD (R PHASE), VOLTAGE THD (Y PHASE), VOLTAGE THD (B PHASE), CURRENT THD (R PHASE), CURRENT THD (Y PHASE), CURRENT THD (B PHASE), KW (R PHASE), KW (Y PHASE), KW (B PHASE), KVAR (R PHASE), KVAR (Y PHASE), KVAR (B PHASE), KWh (DELIVERED), KVAh (DELIVERED), VOLTAGE THD, POWER FACTOR (R PHASE), POWER FACTOR (Y PHASE), POWER FACTOR (B PHASE), CURRENT (NEUTRAL), LAST DEMAND kW, PRESENT DEMAND kW, PREDICTED DEMAND kW, PEAK DEMAND kW, LAST DEMAND kVA, PRESENT DEMAND kVA, PREDICTED DEMAND kVA, PEAK DEMAND kVA, WH DEL + REC, WH DEL - REC, VARH DEL, VARH REC, VARH DEL + REC, VARH DEL - REC, VAH DEL + REC, VAH DEL - REC, Voltage Unbal R Phase, Voltage Unbal Y Phase, Voltage Unbal B Phase, Current Unbal R Phase, Current Unbal Y Phase, Current Unbal B Phase, Pre_Demand_KVAr, Demand_KVAr, Total KWh data, Voltage Unbalance A-B, Voltage Unbalance B-C, Voltage Unbalance C-A, Last Demand(KVAr), Peak Demand(KVAr), Last Demand (A Avg), Present Demand(A Avg), Predicted Demand(A Avg), Peak Demand(A Avg), Total KWH, kWh Total, Total kw, Scope 2 Emission
A3: 1016 | B3: Tata Power Solar Systems Ltd. | C3: 11904 | D3: MV - 2 Raw Power | E3: M28 | F3: 8175657f#3 | G3: TRUE | H3: FALSE | I3: tata_Solar | J3: TPREL | K3: Bangalore | L3: mahadeva.prasad@tatapower.com | M3: 9900283898 | N3: kWh, kW, VOLTAGE (LN), CURRENT, FREQUENCY, Power Factor, KVAR, KVA, KVA (R PHASE), KVA (Y PHASE), KVA (B PHASE), VOLTAGE (LL), VOLTAGE (LL RY Phase), VOLTAGE (LL YB Phase), VOLTAGE (LL BR Phase), VOLTAGE (LN R Phase), VOLTAGE (LN Y PHASE), VOLTAGE (LN B PHASE), CURRENT (R PHASE), CURRENT (Y PHASE), CURRENT (B PHASE), KVAh, VOLTAGE THD (R PHASE), VOLTAGE THD (Y PHASE), VOLTAGE THD (B PHASE), CURRENT THD (R PHASE), CURRENT THD (Y PHASE), CURRENT THD (B PHASE), KVARh (INDUCTIVE RECEIVED), KVARh (CAPACITIVE RECEIVED), MAXIMUM DEMAND, KW (R PHASE), KW (Y PHASE), KW (B PHASE), KVAR (R PHASE), KVAR (Y PHASE), KVAR (B PHASE), KWh (DELIVERED), KVAh (DELIVERED), KVARh (INDUCTIVE DELIVERED), KVARh (CAPACITIVE DELIVERED), VOLTAGE THD, CURRENT THD, POWER FACTOR (R PHASE), POWER FACTOR (Y PHASE), POWER FACTOR (B PHASE), RISING DEMAND, PRESENT DEMAND, ON HOURS, INTERRUPTIONS, Total KWh data, Run Hours Import, Run Hours Export, RAW Power Factor, RAW POWER FACTOR (R PHASE), RAW POWER FACTOR (Y PHASE), RAW POWER FACTOR (B PHASE), Unit Operating Hours, Health Indicator, Scope 1 Emission
A4: 1016 | B4: Tata Power Solar Systems Ltd. | C4: 11903 | D4: MV - 2 Lighting-AC-AC LTG | E4: M142 | F4: 8175657f#2 | G4: TRUE | H4: FALSE | I4: tata_Solar | J4: TPREL | K4: Bangalore | L4: mahadeva.prasad@tatapower.com | M4: 9900283898 | N4: Current Imbalance, Voltage Imbalance, Chiller_COP, kWh, kW, VOLTAGE (LN), CURRENT, FREQUENCY, Power Factor, KVAR, KVA, KVA (R PHASE), KVA (Y PHASE), KVA (B PHASE), VOLTAGE (LL), VOLTAGE (LL RY Phase), VOLTAGE (LL YB Phase), VOLTAGE (LL BR Phase), VOLTAGE (LN R Phase), VOLTAGE (LN Y PHASE), VOLTAGE (LN B PHASE), CURRENT (R PHASE), CURRENT (Y PHASE), CURRENT (B PHASE), KVAh, VOLTAGE THD (R PHASE), VOLTAGE THD (Y PHASE), VOLTAGE THD (B PHASE), CURRENT THD (R PHASE), CURRENT THD (Y PHASE), CURRENT THD (B PHASE), KW (R PHASE), KW (Y PHASE), KW (B PHASE), KVAR (R PHASE), KVAR (Y PHASE), KVAR (B PHASE), KWh (DELIVERED), KVAh (DELIVERED), VOLTAGE THD, CURRENT THD, POWER FACTOR (R PHASE), POWER FACTOR (Y PHASE), POWER FACTOR (B PHASE), CURRENT (NEUTRAL), LAST DEMAND kW, PRESENT DEMAND kW, PREDICTED DEMAND kW, PEAK DEMAND kW, LAST DEMAND kVA, PRESENT DEMAND kVA, PREDICTED DEMAND kVA, PEAK DEMAND kVA, WH DEL + REC, WH DEL - REC, VARH DEL, VARH REC, VARH DEL + REC, VARH DEL - REC, VAH DEL + REC, VAH DEL - REC, Voltage Unbal R Phase, Voltage Unbal Y Phase, Voltage Unbal B Phase, Current Unbal R Phase, Current Unbal Y Phase, Current Unbal B Phase, Pre_Demand_KVAr, Demand_KVAr, Total KWh data, Voltage Unbalance A-B, Voltage Unbalance B-C, Voltage Unbalance C-A, Last Demand(KVAr), Peak Demand(KVAr), Last Demand (A Avg), Present Demand(A Avg), Predicted Demand(A Avg), Peak Demand(A Avg), MD KVA, Total KWH, kWh Total, Total kw, Total_kWh_Data, kWh Total Value, Voltage Imbalance NEMA, Current Imbalance-I/P, V_Y_Ang_cal, V_B_Ang_cal, Angle_Y, Angle_B, V_R_B_Diff, V_R_Y_Diff, V_B_Y_Diff, I_R_B_Diff, I_R_Y_Diff, I_B_Y_Diff, PF_R_B_Diff, PF_R_Y_Diff, PF_B_Y_Diff, COP, Loading%, Scope 2, Total KW, Total chiller kW/TR, Avg Line_Current, IKW/TR comp
A5: 1016 | B5: Tata Power Solar Systems Ltd. | C5: 14012 | D5: UPW Raw Water In Flow Meter | E5: M191 | F5: 862952027124923#2 | G5: TRUE | H5: FALSE | I5: tata_Solar | J5: TPREL | K5: Bangalore | L5: mahadeva.prasad@tatapower.com | M5: 9900283898 | N5: Flow Rate(m3/hr), Reverse Flow Totaliser, Volume (m3/h), Totaliser(m3)
A6: 1016 | B6: Tata Power Solar Systems Ltd. | C6: 35157 | D6: Outgoing To CDA 6,7,8 | E6: M142 | F6: 864524076934649#8 | G6: TRUE | H6: FALSE | I6: tata_Solar | J6: TPREL | K6: Bangalore | L6: mahadeva.prasad@tatapower.com | M6: 9900283898 | N6: Current Imbalance, Voltage Imbalance, Chiller_COP, kWh, kW, VOLTAGE (LN), CURRENT, FREQUENCY, Power Factor, KVAR, KVA, KVA (R PHASE), KVA (Y PHASE), KVA (B PHASE), VOLTAGE (LL), VOLTAGE (LL RY Phase), VOLTAGE (LL YB Phase), VOLTAGE (LL BR Phase), VOLTAGE (LN R Phase), VOLTAGE (LN Y PHASE), VOLTAGE (LN B PHASE), CURRENT (R PHASE), CURRENT (Y PHASE), CURRENT (B PHASE), KVAh, VOLTAGE THD (R PHASE), VOLTAGE THD (Y PHASE), VOLTAGE THD (B PHASE), CURRENT THD (R PHASE), CURRENT THD (Y PHASE), CURRENT THD (B PHASE), KW (R PHASE), KW (Y PHASE), KW (B PHASE), KVAR (R PHASE), KVAR (Y PHASE), KVAR (B PHASE), KWh (DELIVERED), KVAh (DELIVERED), VOLTAGE THD, CURRENT THD, POWER FACTOR (R PHASE), POWER FACTOR (Y PHASE), POWER FACTOR (B PHASE), CURRENT (NEUTRAL), LAST DEMAND kW, PRESENT DEMAND kW, PREDICTED DEMAND kW, PEAK DEMAND kW, LAST DEMAND kVA, PRESENT DEMAND kVA, PREDICTED DEMAND kVA, PEAK DEMAND kVA, WH DEL + REC, WH DEL - REC, VARH DEL, VARH REC, VARH DEL + REC, VARH DEL - REC, VAH DEL + REC, VAH DEL - REC, Voltage Unbal R Phase, Voltage Unbal Y Phase, Voltage Unbal B Phase, Current Unbal R Phase, Current Unbal Y Phase, Current Unbal B Phase, Pre_Demand_KVAr, Demand_KVAr, Total KWh data, Voltage Unbalance A-B, Voltage Unbalance B-C, Voltage Unbalance C-A, Last Demand(KVAr), Peak Demand(KVAr), Last Demand (A Avg), Present Demand(A Avg), Predicted Demand(A Avg), Peak Demand(A Avg), MD KVA, Total KWH, kWh Total, Total kw, Total_kWh_Data, kWh Total Value, Voltage Imbalance NEMA, Current Imbalance-I/P, V_Y_Ang_cal, V_B_Ang_cal, Angle_Y, Angle_B, V_R_B_Diff, V_R_Y_Diff, V_B_Y_Diff, I_R_B_Diff, I_R_Y_Diff, I_B_Y_Diff, PF_R_B_Diff, PF_R_Y_Diff, PF_B_Y_Diff, COP, Loading%, Scope 2, Total KW, Total chiller kW/TR, Avg Line_Current, IKW/TR comp
A7: 1016 | B7: Tata Power Solar Systems Ltd. | C7: 12443 | D7: MV -1 SSB 2 | E7: M142 | F7: 868728038935125#3 | G7: TRUE | H7: FALSE | I7: tata_Solar | J7: TPREL | K7: Bangalore | L7: mahadeva.prasad@tatapower.com | M7: 9900283898 | N7: Current Imbalance, Voltage Imbalance, Chiller_COP, kWh, kW, VOLTAGE (LN), CURRENT, FREQUENCY, Power Factor, KVAR, KVA, KVA (R PHASE), KVA (Y PHASE), KVA (B PHASE), VOLTAGE (LL), VOLTAGE (LL RY Phase), VOLTAGE (LL YB Phase), VOLTAGE (LL BR Phase), VOLTAGE (LN R Phase), VOLTAGE (LN Y PHASE), VOLTAGE (LN B PHASE), CURRENT (R PHASE), CURRENT (Y PHASE), CURRENT (B PHASE), KVAh, VOLTAGE THD (R PHASE), VOLTAGE THD (Y PHASE), VOLTAGE THD (B PHASE), CURRENT THD (R PHASE), CURRENT THD (Y PHASE), CURRENT THD (B PHASE), KW (R PHASE), KW (Y PHASE), KW (B PHASE), KVAR (R PHASE), KVAR (Y PHASE), KVAR (B PHASE), KWh (DELIVERED), KVAh (DELIVERED), VOLTAGE THD, CURRENT THD, POWER FACTOR (R PHASE), POWER FACTOR (Y PHASE), POWER FACTOR (B PHASE), CURRENT (NEUTRAL), LAST DEMAND kW, PRESENT DEMAND kW, PREDICTED DEMAND kW, PEAK DEMAND kW, LAST DEMAND kVA, PRESENT DEMAND kVA, PREDICTED DEMAND kVA, PEAK DEMAND kVA, WH DEL + REC, WH DEL - REC, VARH DEL, VARH REC, VARH DEL + REC, VARH DEL - REC, VAH DEL + REC, VAH DEL - REC, Voltage Unbal R Phase, Voltage Unbal Y Phase, Voltage Unbal B Phase, Current Unbal R Phase, Current Unbal Y Phase, Current Unbal B Phase, Pre_Demand_KVAr, Demand_KVAr, Total KWh data, Voltage Unbalance A-B, Voltage Unbalance B-C, Voltage Unbalance C-A, Last Demand(KVAr), Peak Demand(KVAr), Last Demand (A Avg), Present Demand(A Avg), Predicted Demand(A Avg), Peak Demand(A Avg), MD KVA, Total KWH, kWh Total, Total kw, Total_kWh_Data, kWh Total Value, Voltage Imbalance NEMA, Current Imbalance-I/P, V_Y_Ang_cal, V_B_Ang_cal, Angle_Y, Angle_B, V_R_B_Diff, V_R_Y_Diff, V_B_Y_Diff, I_R_B_Diff, I_R_Y_Diff, I_B_Y_Diff, PF_R_B_Diff, PF_R_Y_Diff, PF_B_Y_Diff, COP, Loading%, Scope 2, Total KW, Total chiller kW/TR, Avg Line_Current, IKW/TR comp
A8: 1016 | B8: Tata Power Solar Systems Ltd. | C8: 34147 | D8: Vega Post Lamp Cooling Chamber | E8: M314 | F8: 868404044681497#3 | G8: TRUE | H8: FALSE | I8: tata_Solar | J8: TPREL | K8: Bangalore | L8: mahadeva.prasad@tatapower.com | M8: 9900283898 | N8: Temperature, Humidity, Dewpoint(Â°C)
A9: 1016 | B9: Tata Power Solar Systems Ltd. | C9: 49120 | D9: ETP RO Permeate | E9: M206 | F9: 862952027124923#5 | G9: TRUE | H9: FALSE | I9: tata_Solar | J9: TPREL | K9: Bangalore | L9: mahadeva.prasad@tatapower.com | M9: 9900283898 | N9: Flow Rate(m3/hr), Totaliser(m3)
A10: 1016 | B10: Tata Power Solar Systems Ltd. | C10: 11907 | D10: Module UPS2 | E10: M28 | F10: 862952027076446#2 | G10: TRUE | H10: FALSE | I10: tata_Solar | J10: TPREL | K10: Bangalore | L10: mahadeva.prasad@tatapower.com | M10: 9900283898 | N10: kWh, kW, VOLTAGE (LN), CURRENT, FREQUENCY, Power Factor, KVAR, KVA, KVA (R PHASE), KVA (Y PHASE), KVA (B PHASE), VOLTAGE (LL), VOLTAGE (LL RY Phase), VOLTAGE (LL YB Phase), VOLTAGE (LL BR Phase), VOLTAGE (LN R Phase), VOLTAGE (LN Y PHASE), VOLTAGE (LN B PHASE), CURRENT (R PHASE), CURRENT (Y PHASE), CURRENT (B PHASE), KVAh, VOLTAGE THD (R PHASE), VOLTAGE THD (Y PHASE), VOLTAGE THD (B PHASE), CURRENT THD (R PHASE), CURRENT THD (Y PHASE), CURRENT THD (B PHASE), KVARh (INDUCTIVE RECEIVED), KVARh (CAPACITIVE RECEIVED), MAXIMUM DEMAND, KW (R PHASE), KW (Y PHASE), KW (B PHASE), KVAR (R PHASE), KVAR (Y PHASE), KVAR (B PHASE), KWh (DELIVERED), KVAh (DELIVERED), KVARh (INDUCTIVE DELIVERED), KVARh (CAPACITIVE DELIVERED), VOLTAGE THD, CURRENT THD, POWER FACTOR (R PHASE), POWER FACTOR (Y PHASE), POWER FACTOR (B PHASE), RISING DEMAND, PRESENT DEMAND, ON HOURS, INTERRUPTIONS, Total KWh data, Run Hours Import, Run Hours Export, RAW Power Factor, RAW POWER FACTOR (R PHASE), RAW POWER FACTOR (Y PHASE), RAW POWER FACTOR (B PHASE), Unit Operating Hours, Health Indicator, Scope 1 Emission
A11: 1016 | B11: Tata Power Solar Systems Ltd. | C11: 11883 | D11: Kaeser Compressor New Oil Free | E11: M142 | F11: 864524076934649#1 | G11: TRUE | H11: FALSE | I11: tata_Solar | J11: TPREL | K11: Bangalore | L11: mahadeva.prasad@tatapower.com | M11: 9900283898 | N11: Current Imbalance, Voltage Imbalance, Chiller_COP, kWh, kW, VOLTAGE (LN), CURRENT, FREQUENCY, Power Factor, KVAR, KVA, KVA (R PHASE), KVA (Y PHASE), KVA (B PHASE), VOLTAGE (LL), VOLTAGE (LL RY Phase), VOLTAGE (LL YB Phase), VOLTAGE (LL BR Phase), VOLTAGE (LN R Phase), VOLTAGE (LN Y PHASE), VOLTAGE (LN B PHASE), CURRENT (R PHASE), CURRENT (Y PHASE), CURRENT (B PHASE), KVAh, VOLTAGE THD (R PHASE), VOLTAGE THD (Y PHASE), VOLTAGE THD (B PHASE), CURRENT THD (R PHASE), CURRENT THD (Y PHASE), CURRENT THD (B PHASE), KW (R PHASE), KW (Y PHASE), KW (B PHASE), KVAR (R PHASE), KVAR (Y PHASE), KVAR (B PHASE), KWh (DELIVERED), KVAh (DELIVERED), VOLTAGE THD, CURRENT THD, POWER FACTOR (R PHASE), POWER FACTOR (Y PHASE), POWER FACTOR (B PHASE), CURRENT (NEUTRAL), LAST DEMAND kW, PRESENT DEMAND kW, PREDICTED DEMAND kW, PEAK DEMAND kW, LAST DEMAND kVA, PRESENT DEMAND kVA, PREDICTED DEMAND kVA, PEAK DEMAND kVA, WH DEL + REC, WH DEL - REC, VARH DEL, VARH REC, VARH DEL + REC, VARH DEL - REC, VAH DEL + REC, VAH DEL - REC, Voltage Unbal R Phase, Voltage Unbal Y Phase, Voltage Unbal B Phase, Current Unbal R Phase, Current Unbal Y Phase, Current Unbal B Phase, Pre_Demand_KVAr, Demand_KVAr, Total KWh data, Voltage Unbalance A-B, Voltage Unbalance B-C, Voltage Unbalance C-A, Last Demand(KVAr), Peak Demand(KVAr), Last Demand (A Avg), Present Demand(A Avg), Predicted Demand(A Avg), Peak Demand(A Avg), MD KVA, Total KWH, kWh Total, Total kw, Total_kWh_Data, kWh Total Value, Voltage Imbalance NEMA, Current Imbalance-I/P, V_Y_Ang_cal, V_B_Ang_cal, Angle_Y, Angle_B, V_R_B_Diff, V_R_Y_Diff, V_B_Y_Diff, I_R_B_Diff, I_R_Y_Diff, I_B_Y_Diff, PF_R_B_Diff, PF_R_Y_Diff, PF_B_Y_Diff, COP, Loading%, Scope 2, Total KW, Total chiller kW/TR, Avg Line_Current, IKW/TR comp
A12: 1016 | B12: Tata Power Solar Systems Ltd. | C12: 35154 | D12: CELL HEXA Line SMSB-2 | E12: M142 | F12: 864524076934649#5 | G12: TRUE | H12: FALSE | I12: tata_Solar | J12: TPREL | K12: Bangalore | L12: mahadeva.prasad@tatapower.com | M12: 9900283898 | N12: Current Imbalance, Voltage Imbalance, Chiller_COP, kWh, kW, VOLTAGE (LN), CURRENT, FREQUENCY, Power Factor, KVAR, KVA, KVA (R PHASE), KVA (Y PHASE), KVA (B PHASE), VOLTAGE (LL), VOLTAGE (LL RY Phase), VOLTAGE (LL YB Phase), VOLTAGE (LL BR Phase), VOLTAGE (LN R Phase), VOLTAGE (LN Y PHASE), VOLTAGE (LN B PHASE), CURRENT (R PHASE), CURRENT (Y PHASE), CURRENT (B PHASE), KVAh, VOLTAGE THD (R PHASE), VOLTAGE THD (Y PHASE), VOLTAGE THD (B PHASE), CURRENT THD (R PHASE), CURRENT THD (Y PHASE), CURRENT THD (B PHASE), KW (R PHASE), KW (Y PHASE), KW (B PHASE), KVAR (R PHASE), KVAR (Y PHASE), KVAR (B PHASE), KWh (DELIVERED), KVAh (DELIVERED), VOLTAGE THD, CURRENT THD, POWER FACTOR (R PHASE), POWER FACTOR (Y PHASE), POWER FACTOR (B PHASE), CURRENT (NEUTRAL), LAST DEMAND kW, PRESENT DEMAND kW, PREDICTED DEMAND kW, PEAK DEMAND kW, LAST DEMAND kVA, PRESENT DEMAND kVA, PREDICTED DEMAND kVA, PEAK DEMAND kVA, WH DEL + REC, WH DEL - REC, VARH DEL, VARH REC, VARH DEL + REC, VARH DEL - REC, VAH DEL + REC, VAH DEL - REC, Voltage Unbal R Phase, Voltage Unbal Y Phase, Voltage Unbal B Phase, Current Unbal R Phase, Current Unbal Y Phase, Current Unbal B Phase, Pre_Demand_KVAr, Demand_KVAr, Total KWh data, Voltage Unbalance A-B, Voltage Unbalance B-C, Voltage Unbalance C-A, Last Demand(KVAr), Peak Demand(KVAr), Last Demand (A Avg), Present Demand(A Avg), Predicted Demand(A Avg), Peak Demand(A Avg), MD KVA, Total KWH, kWh Total, Total kw, Total_kWh_Data, kWh Total Value, Voltage Imbalance NEMA, Current Imbalance-I/P, V_Y_Ang_cal, V_B_Ang_cal, Angle_Y, Angle_B, V_R_B_Diff, V_R_Y_Diff, V_B_Y_Diff, I_R_B_Diff, I_R_Y_Diff, I_B_Y_Diff, PF_R_B_Diff, PF_R_Y_Diff, PF_B_Y_Diff, COP, Loading%, Scope 2, Total KW, Total chiller kW/TR, Avg Line_Current, IKW/TR comp
... A119: 1016 | B119: Tata Power Solar Systems Ltd. | C119: 59233 | D119: FAD - Modula line | E119: M466 | F119: 862952027093516#1 | G119: TRUE | H119: FALSE | I119: tata_Solar | J119: TPREL | K119: Bangalore | L119: mahadeva.prasad@tatapower.com | M119: 9900283898 | N119: Totaliser(Kg), Flow Rate(Kg/hr)

Sheet  Morning peak
E3: Unit 1 EB Incomer | F3: Unit 5 EB Incomer | G3: Unit 1 DG 1 - 365KVA | H3: Unit 1 DG 2 - 380KVA | I3: Unit 5 DG Incomer
E4: 12819 | F4: 13578 | G4: 12817 | H4: 12818 | I4: 13579
A5: 462350.25 | B5: 46235 | C5: 0.25 | D5: 0.29166667 | E5: 52.6375 | F5: 15.896723 | G5: 0 | H5: 0 | I5: 0
A6: 462350.291666666666667 | B6: 46235 | C6: 0.29166667 | D6: 0.33333333 | E6: 64.666667 | F6: 27.887652 | G6: 0 | H6: 0 | I6: 0
A7: 462350.333333333333333 | B7: 46235 | C7: 0.33333333 | D7: 0.375 | E7: 68.410452 | F7: 11.201488 | G7: 0 | H7: 0 | I7: 0
A8: 462350.375 | B8: 46235 | C8: 0.375 | D8: 0.41666667 | E8: 64.560381 | F8: 11.452381 | G8: 0 | H8: 0 | I8: 0
A9: 462360.25 | B9: 46236 | C9: 0.25 | D9: 0.29166667 | E9: 40.192213 | F9: 3.25 | G9: 0 | H9: 0 | I9: 0
A10: 462360.291666666666667 | B10: 46236 | C10: 0.29166667 | D10: 0.33333333 | E10: 41.4375 | F10: 2.7046875 | G10: 0 | H10: 0 | I10: 0
A11: 462360.333333333333333 | B11: 46236 | C11: 0.33333333 | D11: 0.375 | E11: 43.154167 | F11: 2.6640625 | G11: 0 | H11: 0 | I11: 0
A12: 462360.375 | B12: 46236 | C12: 0.375 | D12: 0.41666667 | E12: 40.700282 | F12: 2.88125 | G12: 0 | H12: 0 | I12: 0
A13: 462370.25 | B13: 46237 | C13: 0.25 | D13: 0.29166667 | E13: 67.304661 | F13: 16.634375 | G13: 0 | H13: 0 | I13: 0
A14: 462370.291666666666667 | B14: 46237 | C14: 0.29166667 | D14: 0.33333333 | E14: 83.125 | F14: 12.809375 | G14: 0 | H14: 0 | I14: 0
A15: 462370.333333333333333 | B15: 46237 | C15: 0.33333333 | D15: 0.375 | E15: 98.491667 | F15: 16.86875 | G15: 0 | H15: 0 | I15: 0
A16: 462370.375 | B16: 46237 | C16: 0.375 | D16: 0.41666667 | E16: 111.84109 | F16: 11.709375 | G16: 0 | H16: 0 | I16: 0
... A128: 462650.375 | B128: 46265 | C128: 0.375 | D128: 0.41666667 | E128: 0 | F128: 0 | G128: 0 | H128: 0 | I128: 0

Sheet Evening Peak
E3: Unit 1 EB Incomer | F3: Unit 5 EB Incomer | G3: Unit 1 DG 1 - 365KVA | H3: Unit 1 DG 2 - 380KVA | I3: Unit 5 DG Incomer
E4: 12819 | F4: 13578 | G4: 12817 | H4: 12818 | I4: 13579
A5: 462350.75 | B5: 46235 | C5: 0.75 | D5: 0.79166667 | E5: 59.998907 | F5: 15.80625 | G5: 0 | H5: 0 | I5: 0
A6: 462350.791666666666667 | B6: 46235 | C6: 0.79166667 | D6: 0.83333333 | E6: 55.433333 | F6: 19.103125 | G6: 0 | H6: 0 | I6: 0
A7: 462350.833333333333333 | B7: 46235 | C7: 0.83333333 | D7: 0.875 | E7: 51.466667 | F7: 31.942187 | G7: 0 | H7: 0 | I7: 0
A8: 462350.875 | B8: 46235 | C8: 0.875 | D8: 0.91666667 | E8: 50.916667 | F8: 29.385938 | G8: 0 | H8: 0 | I8: 0
A9: 462360.75 | B9: 46236 | C9: 0.75 | D9: 0.79166667 | E9: 65.830328 | F9: 3.7921875 | G9: 0 | H9: 0 | I9: 0
A10: 462360.791666666666667 | B10: 46236 | C10: 0.79166667 | D10: 0.83333333 | E10: 49.095902 | F10: 5.415625 | G10: 0 | H10: 0 | I10: 0
A11: 462360.833333333333333 | B11: 46236 | C11: 0.83333333 | D11: 0.875 | E11: 10.295989 | F11: 5.353125 | G11: 34.468099 | H11: 0 | I11: 0
A12: 462360.875 | B12: 46236 | C12: 0.875 | D12: 0.91666667 | E12: 0.054285542 | F12: 5.4721799 | G12: 46.832292 | H12: 0 | I12: 0
A13: 462370.75 | B13: 46237 | C13: 0.75 | D13: 0.79166667 | E13: 94.297989 | F13: 13.865385 | G13: 0 | H13: 0 | I13: 0
A14: 462370.791666666666667 | B14: 46237 | C14: 0.79166667 | D14: 0.83333333 | E14: 76.1 | F14: 17.642188 | G14: 0 | H14: 0 | I14: 0
A15: 462370.833333333333333 | B15: 46237 | C15: 0.83333333 | D15: 0.875 | E15: 61.404167 | F15: 28.519398 | G15: 0 | H15: 0 | I15: 0
A16: 462370.875 | B16: 46237 | C16: 0.875 | D16: 0.91666667 | E16: 47.6875 | F16: 33.244665 | G16: 0 | H16: 0 | I16: 0
... A128: 462650.875 | B128: 46265 | C128: 0.875 | D128: 0.91666667 | E128: 0 | F128: 0 | G128: 0 | H128: 0 | I128: 0
B129: 46266 | C129: 0.75 | D129: 0.79166667
B130: 46266 | C130: 0.79166667 | D130: 0.83333333
B131: 46266 | C131: 0.83333333 | D131: 0.875
B132: 46266 | C132: 0.875 | D132: 0.91666667

Sheet Normal time
E3: Unit 1 EB Incomer | F3: Unit 5 EB Incomer | G3: Unit 1 DG 1 - 365KVA | H3: Unit 1 DG 2 - 380KVA | I3: Unit 5 DG Incomer
E4: 12819 | F4: 13578 | G4: 12817 | H4: 12818 | I4: 13579
A5: 462350.416666666666667 | B5: 46235 | C5: 0.41666667 | D5: 0.45833333 | E5: 66.645833 | F5: 8.2103938 | G5: 0 | H5: 0 | I5: 0
A6: 462350.458333333333333 | B6: 46235 | C6: 0.45833333 | D6: 0.5 | E6: 72.3 | F6: 9.9716747 | G6: 0 | H6: 0 | I6: 0
A7: 462350.5 | B7: 46235 | C7: 0.5 | D7: 0.54166667 | E7: 105.14167 | F7: 10.45 | G7: 0 | H7: 0 | I7: 0
A8: 462350.541666666666667 | B8: 46235 | C8: 0.54166667 | D8: 0.58333333 | E8: 97.308333 | F8: 11.764062 | G8: 0 | H8: 0 | I8: 0
A9: 462350.583333333333333 | B9: 46235 | C9: 0.58333333 | D9: 0.625 | E9: 103.21667 | F9: 10.44497 | G9: 0 | H9: 0 | I9: 0
A10: 462350.625 | B10: 46235 | C10: 0.625 | D10: 0.66666667 | E10: 99.033333 | F10: 7.5956555 | G10: 0 | H10: 0 | I10: 0
A11: 462350.666666666666667 | B11: 46235 | C11: 0.66666667 | D11: 0.70833333 | E11: 87.883333 | F11: 12.2375 | G11: 0 | H11: 0 | I11: 0
A12: 462350.708333333333333 | B12: 46235 | C12: 0.70833333 | D12: 0.75 | E12: 87.96776 | F12: 14.065625 | G12: 0 | H12: 0 | I12: 0
A13: 462360.416666666666667 | B13: 46236 | C13: 0.41666667 | D13: 0.45833333 | E13: 36.720551 | F13: 2.6984375 | G13: 0 | H13: 0 | I13: 0
